Workbook

Sheet bid input
A1: time | B1: bidID | C1: Bid Type | D1: if general: Aggregate $ | E1: if general, max % per asset | F1: if specified, bid % | G1: if specified, loan or MO | H1: Loan # if applicable | I1: MO if applicable | J1: order type | K1: if competitive, bid rate | L1: order timing | M1: Funds available | N1: If auto, date/time order placed | O1: Specified & Competitive | P1: Specified & Noncompetitive | Q1: General & Competitive | R1: General & Noncompetitive | S1: time
A2: 0.625 | B2: 1104134 | C2: General | D2: 15000000 | E2: 0.1 | J2: Noncompetitive | L2: Auto | M2: 187500 | N2: 40892.537 | O2: =+IF(AND(C2="Specified",J2="Competitive"),1,0) -> 0 | P2: =+IF(AND(C2="Specified",J2="Noncompetitive"),1,0) -> 0 | Q2: =+IF(AND(C2="General",J2="Competitive"),1,0) -> 0 | R2: =+IF(AND(C2="General",J2="Noncompetitive"),1,0) -> 1 | S2: 40928.625
A3: 0.625 | B3: 1104143 | C3: Specified | F3: 0.2 | G3: MO | I3: ABC Mortgage | J3: Noncompetitive | L3: Auto | M3: 500000 | N3: 40897.364 | O3: =+IF(AND(C3="Specified",J3="Competitive"),1,0) -> 0 | P3: =+IF(AND(C3="Specified",J3="Noncompetitive"),1,0) -> 1 | Q3: =+IF(AND(C3="General",J3="Competitive"),1,0) -> 0 | R3: =+IF(AND(C3="General",J3="Noncompetitive"),1,0) -> 0 | S3: 40928.625
A4: 0.625 | B4: 1104154 | C4: General | D4: 20000000 | E4: 0.2 | J4: Competitive | K4: 0.03 | L4: Auto | M4: 185000 | N4: 40913.387 | O4: =+IF(AND(C4="Specified",J4="Competitive"),1,0) -> 0 | P4: =+IF(AND(C4="Specified",J4="Noncompetitive"),1,0) -> 0 | Q4: =+IF(AND(C4="General",J4="Competitive"),1,0) -> 1 | R4: =+IF(AND(C4="General",J4="Noncompetitive"),1,0) -> 0 | S4: 40928.625
A5: 0.625 | B5: 1104152 | C5: Specified | F5: 0.2 | G5: MO | I5: Prime Lending | J5: Competitive | K5: 0.03 | L5: Auto | M5: 1500000 | N5: 40913.386 | O5: =+IF(AND(C5="Specified",J5="Competitive"),1,0) -> 1 | P5: =+IF(AND(C5="Specified",J5="Noncompetitive"),1,0) -> 0 | Q5: =+IF(AND(C5="General",J5="Competitive"),1,0) -> 0 | R5: =+IF(AND(C5="General",J5="Noncompetitive"),1,0) -> 0 | S5: 40928.625
A6: 0.71263889 | B6: 1104136 | C6: Specified | F6: 0.2 | G6: Loan | H6: 4 | J6: Competitive | K6: 0.06 | L6: Day Trade | M6: 860000 | O6: =+IF(AND(C6="Specified",J6="Competitive"),1,0) -> 1 | P6: =+IF(AND(C6="Specified",J6="Noncompetitive"),1,0) -> 0 | Q6: =+IF(AND(C6="General",J6="Competitive"),1,0) -> 0 | R6: =+IF(AND(C6="General",J6="Noncompetitive"),1,0) -> 0 | S6: 40928.713
A7: 0.77263889 | B7: 1104138 | C7: General | D7: 1000000 | E7: 0.5 | J7: Competitive | K7: 0.02125 | L7: Day Trade | M7: 300000 | O7: =+IF(AND(C7="Specified",J7="Competitive"),1,0) -> 0 | P7: =+IF(AND(C7="Specified",J7="Noncompetitive"),1,0) -> 0 | Q7: =+IF(AND(C7="General",J7="Competitive"),1,0) -> 1 | R7: =+IF(AND(C7="General",J7="Noncompetitive"),1,0) -> 0 | S7: 40928.773
A8: 0.80263889 | B8: 1104139 | C8: General | D8: 500000 | E8: 0.3 | J8: Competitive | K8: 0.0225 | L8: Day Trade | M8: 250000 | O8: =+IF(AND(C8="Specified",J8="Competitive"),1,0) -> 0 | P8: =+IF(AND(C8="Specified",J8="Noncompetitive"),1,0) -> 0 | Q8: =+IF(AND(C8="General",J8="Competitive"),1,0) -> 1 | R8: =+IF(AND(C8="General",J8="Noncompetitive"),1,0) -> 0 | S8: 40928.803
A9: 0.83263889 | B9: 1104140 | C9: Specified | F9: 0.2 | G9: Loan | H9: 5 | J9: Competitive | K9: 0.025 | L9: Day Trade | M9: 74000 | O9: =+IF(AND(C9="Specified",J9="Competitive"),1,0) -> 1 | P9: =+IF(AND(C9="Specified",J9="Noncompetitive"),1,0) -> 0 | Q9: =+IF(AND(C9="General",J9="Competitive"),1,0) -> 0 | R9: =+IF(AND(C9="General",J9="Noncompetitive"),1,0) -> 0 | S9: 40928.833
A10: 0.86263889 | B10: 1104141 | C10: General | D10: 500000 | E10: 0.2 | J10: Competitive | K10: 0.025 | L10: Day Trade | M10: 285000 | O10: =+IF(AND(C10="Specified",J10="Competitive"),1,0) -> 0 | P10: =+IF(AND(C10="Specified",J10="Noncompetitive"),1,0) -> 0 | Q10: =+IF(AND(C10="General",J10="Competitive"),1,0) -> 1 | R10: =+IF(AND(C10="General",J10="Noncompetitive"),1,0) -> 0 | S10: 40928.863
A11: 0.90263889 | B11: 1104159 | C11: Specified | F11: 0.2 | G11: Loan | H11: 1 | J11: Noncompetitive | L11: Day Trade | M11: 532000 | O11: =+IF(AND(C11="Specified",J11="Competitive"),1,0) -> 0 | P11: =+IF(AND(C11="Specified",J11="Noncompetitive"),1,0) -> 1 | Q11: =+IF(AND(C11="General",J11="Competitive"),1,0) -> 0 | R11: =+IF(AND(C11="General",J11="Noncompetitive"),1,0) -> 0 | S11: 40928.903
A12: 0.96263889 | B12: 1104161 | C12: Specified | F12: 0.2 | G12: Loan | H12: 4 | J12: Noncompetitive | L12: Day Trade | M12: 292000 | O12: =+IF(AND(C12="Specified",J12="Competitive"),1,0) -> 0 | P12: =+IF(AND(C12="Specified",J12="Noncompetitive"),1,0) -> 1 | Q12: =+IF(AND(C12="General",J12="Competitive"),1,0) -> 0 | R12: =+IF(AND(C12="General",J12="Noncompetitive"),1,0) -> 0 | S12: 40928.963
A13: 0.98263889 | B13: 1104145 | C13: Specified | F13: 0.1 | G13: Loan | H13: 1 | J13: Competitive | K13: 0.015 | L13: Day Trade | M13: 752000 | O13: =+IF(AND(C13="Specified",J13="Competitive"),1,0) -> 1 | P13: =+IF(AND(C13="Specified",J13="Noncompetitive"),1,0) -> 0 | Q13: =+IF(AND(C13="General",J13="Competitive"),1,0) -> 0 | R13: =+IF(AND(C13="General",J13="Noncompetitive"),1,0) -> 0 | S13: 40928.983
A14: 1.0993056 | B14: 1104133 | C14: Specified | F14: 0.2 | G14: Loan | H14: 4 | J14: Competitive | K14: 0.04 | L14: Day Trade | M14: 418000 | O14: =+IF(AND(C14="Specified",J14="Competitive"),1,0) -> 1 | P14: =+IF(AND(C14="Specified",J14="Noncompetitive"),1,0) -> 0 | Q14: =+IF(AND(C14="General",J14="Competitive"),1,0) -> 0 | R14: =+IF(AND(C14="General",J14="Noncompetitive"),1,0) -> 0 | S14: 40929.099
A15: 1.1026389 | B15: 1104149 | C15: Specified | F15: 0.2 | G15: Loan | H15: 5 | J15: Noncompetitive | L15: Day Trade | M15: 47000 | O15: =+IF(AND(C15="Specified",J15="Competitive"),1,0) -> 0 | P15: =+IF(AND(C15="Specified",J15="Noncompetitive"),1,0) -> 1 | Q15: =+IF(AND(C15="General",J15="Competitive"),1,0) -> 0 | R15: =+IF(AND(C15="General",J15="Noncompetitive"),1,0) -> 0 | S15: 40929.103
A16: 1.1626389 | B16: 1104151 | C16: Specified | F16: 0.2 | G16: Loan | H16: 1 | J16: Noncompetitive | L16: Day Trade | M16: 283000 | O16: =+IF(AND(C16="Specified",J16="Competitive"),1,0) -> 0 | P16: =+IF(AND(C16="Specified",J16="Noncompetitive"),1,0) -> 1 | Q16: =+IF(AND(C16="General",J16="Competitive"),1,0) -> 0 | R16: =+IF(AND(C16="General",J16="Noncompetitive"),1,0) -> 0 | S16: 40929.163
A17: 1.1926389 | B17: 1104131 | C17: General | D17: 1000000 | E17: 0.5 | J17: Noncompetitive | L17: Day Trade | M17: 598000 | O17: =+IF(AND(C17="Specified",J17="Competitive"),1,0) -> 0 | P17: =+IF(AND(C17="Specified",J17="Noncompetitive"),1,0) -> 0 | Q17: =+IF(AND(C17="General",J17="Competitive"),1,0) -> 0 | R17: =+IF(AND(C17="General",J17="Noncompetitive"),1,0) -> 1 | S17: 40929.193
A18: 1.2826389 | B18: 1104155 | C18: Specified | F18: 0.2 | G18: MO | I18: Best Loans Inc | J18: Competitive | K18: 0.02125 | L18: Day Trade | M18: 639000 | O18: =+IF(AND(C18="Specified",J18="Competitive"),1,0) -> 1 | P18: =+IF(AND(C18="Specified",J18="Noncompetitive"),1,0) -> 0 | Q18: =+IF(AND(C18="General",J18="Competitive"),1,0) -> 0 | R18: =+IF(AND(C18="General",J18="Noncompetitive"),1,0) -> 0 | S18: 40929.283
A19: 1.3126389 | B19: 1104156 | C19: Specified | F19: 0.2 | G19: Loan | H19: 2 | J19: Noncompetitive | L19: Day Trade | M19: 274000 | O19: =+IF(AND(C19="Specified",J19="Competitive"),1,0) -> 0 | P19: =+IF(AND(C19="Specified",J19="Noncompetitive"),1,0) -> 1 | Q19: =+IF(AND(C19="General",J19="Competitive"),1,0) -> 0 | R19: =+IF(AND(C19="General",J19="Noncompetitive"),1,0) -> 0 | S19: 40929.313
A20: 1.3426389 | B20: 1104157 | C20: General | D20: 1000000 | E20: 0.3 | J20: Noncompetitive | L20: Day Trade | M20: 629000 | O20: =+IF(AND(C20="Specified",J20="Competitive"),1,0) -> 0 | P20: =+IF(AND(C20="Specified",J20="Noncompetitive"),1,0) -> 0 | Q20: =+IF(AND(C20="General",J20="Competitive"),1,0) -> 0 | R20: =+IF(AND(C20="General",J20="Noncompetitive"),1,0) -> 1 | S20: 40929.343
A21: 1.3726389 | B21: 1104158 | C21: Specified | F21: 0.2 | G21: Loan | H21: 1 | J21: Competitive | K21: 0.0225 | L21: Day Trade | M21: 562000 | O21: =+IF(AND(C21="Specified",J21="Competitive"),1,0) -> 1 | P21: =+IF(AND(C21="Specified",J21="Noncompetitive"),1,0) -> 0 | Q21: =+IF(AND(C21="General",J21="Competitive"),1,0) -> 0 | R21: =+IF(AND(C21="General",J21="Noncompetitive"),1,0) -> 0 | S21: 40929.373

Sheet assets available for bid
F1: Allocation process:
E2: Loan Number | G2: 1 | H2: 2 | I2: 3 | J2: 4 | K2: 5 | L2: 6 | M2: Batch Total
E3: MO | G3: ABC Mortgage | H3: ABC Mortgage | I3: Prime Lending | J3: Prime Lending | K3: Best Loans Inc | L3: Integrity Lending
E4: Loan Amount | G4: 318725 | H4: 375685 | I4: 479875 | J4: 525400 | K4: 515425 | L4: 485000 | M4: =SUM(G4:L4) -> 2700110
A6: Step 2 of process - Assets are assigned Specified/Competitive bids:
B7: Bid ID | C7: Loan # | D7: MO | E7: Specific & Competitive? | F7: Rate
B8: =+'bid input'!B2 -> 1104134 | C8: =+'bid input'!H2 -> 0 | D8: =+'bid input'!I2 -> 0 | E8: =+IF('bid input'!O2=1,"Y","N") -> N | F8: =+'bid input'!K2 | G8: =+IF(AND(IsSC="Y",LoanN_SC=LoanNumber,LoanN_SC>0),S_Percent,IF(AND(IsSC="Y",S_MO=MO,LoanN_SC=0),S_Percent,0))*LoanAmount -> 0 | H8: =+IF(AND(IsSC="Y",LoanN_SC=LoanNumber,LoanN_SC>0),S_Percent,IF(AND(IsSC="Y",S_MO=MO,LoanN_SC=0),S_Percent,0))*LoanAmount -> 0 | I8: =+IF(AND(IsSC="Y",LoanN_SC=LoanNumber,LoanN_SC>0),S_Percent,IF(AND(IsSC="Y",S_MO=MO,LoanN_SC=0),S_Percent,0))*LoanAmount -> 0 | J8: =+IF(AND(IsSC="Y",LoanN_SC=LoanNumber,LoanN_SC>0),S_Percent,IF(AND(IsSC="Y",S_MO=MO,LoanN_SC=0),S_Percent,0))*LoanAmount -> 0 | K8: =+IF(AND(IsSC="Y",LoanN_SC=LoanNumber,LoanN_SC>0),S_Percent,IF(AND(IsSC="Y",S_MO=MO,LoanN_SC=0),S_Percent,0))*LoanAmount -> 0 | L8: =+IF(AND(IsSC="Y",LoanN_SC=LoanNumber,LoanN_SC>0),S_Percent,IF(AND(IsSC="Y",S_MO=MO,LoanN_SC=0),S_Percent,0))*LoanAmount -> 0 | M8: =SUM(G8:L8) -> 0 | N8: ='bid input'!F2
B9: =+'bid input'!B3 -> 1104143 | C9: =+'bid input'!H3 -> 0 | D9: =+'bid input'!I3 -> ABC Mortgage | E9: =+IF('bid input'!O3=1,"Y","N") -> N | F9: =+'bid input'!K3 | G9: =+IF(AND(IsSC="Y",LoanN_SC=LoanNumber,LoanN_SC>0),S_Percent,IF(AND(IsSC="Y",S_MO=MO,LoanN_SC=0),S_Percent,0))*LoanAmount -> 0 | H9: =+IF(AND(IsSC="Y",LoanN_SC=LoanNumber,LoanN_SC>0),S_Percent,IF(AND(IsSC="Y",S_MO=MO,LoanN_SC=0),S_Percent,0))*LoanAmount -> 0 | I9: =+IF(AND(IsSC="Y",LoanN_SC=LoanNumber,LoanN_SC>0),S_Percent,IF(AND(IsSC="Y",S_MO=MO,LoanN_SC=0),S_Percent,0))*LoanAmount -> 0 | J9: =+IF(AND(IsSC="Y",LoanN_SC=LoanNumber,LoanN_SC>0),S_Percent,IF(AND(IsSC="Y",S_MO=MO,LoanN_SC=0),S_Percent,0))*LoanAmount -> 0 | K9: =+IF(AND(IsSC="Y",LoanN_SC=LoanNumber,LoanN_SC>0),S_Percent,IF(AND(IsSC="Y",S_MO=MO,LoanN_SC=0),S_Percent,0))*LoanAmount -> 0 | L9: =+IF(AND(IsSC="Y",LoanN_SC=LoanNumber,LoanN_SC>0),S_Percent,IF(AND(IsSC="Y",S_MO=MO,LoanN_SC=0),S_Percent,0))*LoanAmount -> 0 | M9: =SUM(G9:L9) -> 0 | N9: ='bid input'!F3
B10: =+'bid input'!B4 -> 1104154 | C10: =+'bid input'!H4 -> 0 | D10: =+'bid input'!I4 -> 0 | E10: =+IF('bid input'!O4=1,"Y","N") -> N | F10: =+'bid input'!K4 | G10: =+IF(AND(IsSC="Y",LoanN_SC=LoanNumber,LoanN_SC>0),S_Percent,IF(AND(IsSC="Y",S_MO=MO,LoanN_SC=0),S_Percent,0))*LoanAmount -> 0 | H10: =+IF(AND(IsSC="Y",LoanN_SC=LoanNumber,LoanN_SC>0),S_Percent,IF(AND(IsSC="Y",S_MO=MO,LoanN_SC=0),S_Percent,0))*LoanAmount -> 0 | I10: =+IF(AND(IsSC="Y",LoanN_SC=LoanNumber,LoanN_SC>0),S_Percent,IF(AND(IsSC="Y",S_MO=MO,LoanN_SC=0),S_Percent,0))*LoanAmount -> 0 | J10: =+IF(AND(IsSC="Y",LoanN_SC=LoanNumber,LoanN_SC>0),S_Percent,IF(AND(IsSC="Y",S_MO=MO,LoanN_SC=0),S_Percent,0))*LoanAmount -> 0 | K10: =+IF(AND(IsSC="Y",LoanN_SC=LoanNumber,LoanN_SC>0),S_Percent,IF(AND(IsSC="Y",S_MO=MO,LoanN_SC=0),S_Percent,0))*LoanAmount -> 0 | L10: =+IF(AND(IsSC="Y",LoanN_SC=LoanNumber,LoanN_SC>0),S_Percent,IF(AND(IsSC="Y",S_MO=MO,LoanN_SC=0),S_Percent,0))*LoanAmount -> 0 | M10: =SUM(G10:L10) -> 0 | N10: ='bid input'!F4
B11: =+'bid input'!B5 -> 1104152 | C11: =+'bid input'!H5 -> 0 | D11: =+'bid input'!I5 -> Prime Lending | E11: =+IF('bid input'!O5=1,"Y","N") -> Y | F11: =+'bid input'!K5 | G11: =+IF(AND(IsSC="Y",LoanN_SC=LoanNumber,LoanN_SC>0),S_Percent,IF(AND(IsSC="Y",S_MO=MO,LoanN_SC=0),S_Percent,0))*LoanAmount -> 0 | H11: =+IF(AND(IsSC="Y",LoanN_SC=LoanNumber,LoanN_SC>0),S_Percent,IF(AND(IsSC="Y",S_MO=MO,LoanN_SC=0),S_Percent,0))*LoanAmount -> 0 | I11: =+IF(AND(IsSC="Y",LoanN_SC=LoanNumber,LoanN_SC>0),S_Percent,IF(AND(IsSC="Y",S_MO=MO,LoanN_SC=0),S_Percent,0))*LoanAmount -> 95975 | J11: =+IF(AND(IsSC="Y",LoanN_SC=LoanNumber,LoanN_SC>0),S_Percent,IF(AND(IsSC="Y",S_MO=MO,LoanN_SC=0),S_Percent,0))*LoanAmount -> 105080 | K11: =+IF(AND(IsSC="Y",LoanN_SC=LoanNumber,LoanN_SC>0),S_Percent,IF(AND(IsSC="Y",S_MO=MO,LoanN_SC=0),S_Percent,0))*LoanAmount -> 0 | L11: =+IF(AND(IsSC="Y",LoanN_SC=LoanNumber,LoanN_SC>0),S_Percent,IF(AND(IsSC="Y",S_MO=MO,LoanN_SC=0),S_Percent,0))*LoanAmount -> 0 | M11: =SUM(G11:L11) -> 201055 | N11: ='bid input'!F5
B12: =+'bid input'!B6 -> 1104136 | C12: =+'bid input'!H6 -> 4 | D12: =+'bid input'!I6 -> 0 | E12: =+IF('bid input'!O6=1,"Y","N") -> Y | F12: =+'bid input'!K6 | G12: =+IF(AND(IsSC="Y",LoanN_SC=LoanNumber,LoanN_SC>0),S_Percent,IF(AND(IsSC="Y",S_MO=MO,LoanN_SC=0),S_Percent,0))*LoanAmount -> 0 | H12: =+IF(AND(IsSC="Y",LoanN_SC=LoanNumber,LoanN_SC>0),S_Percent,IF(AND(IsSC="Y",S_MO=MO,LoanN_SC=0),S_Percent,0))*LoanAmount -> 0 | I12: =+IF(AND(IsSC="Y",LoanN_SC=LoanNumber,LoanN_SC>0),S_Percent,IF(AND(IsSC="Y",S_MO=MO,LoanN_SC=0),S_Percent,0))*LoanAmount -> 0 | J12: =+IF(AND(IsSC="Y",LoanN_SC=LoanNumber,LoanN_SC>0),S_Percent,IF(AND(IsSC="Y",S_MO=MO,LoanN_SC=0),S_Percent,0))*LoanAmount -> 105080 | K12: =+IF(AND(IsSC="Y",LoanN_SC=LoanNumber,LoanN_SC>0),S_Percent,IF(AND(IsSC="Y",S_MO=MO,LoanN_SC=0),S_Percent,0))*LoanAmount -> 0 | L12: =+IF(AND(IsSC="Y",LoanN_SC=LoanNumber,LoanN_SC>0),S_Percent,IF(AND(IsSC="Y",S_MO=MO,LoanN_SC=0),S_Percent,0))*LoanAmount -> 0 | M12: =SUM(G12:L12) -> 105080 | N12: ='bid input'!F6
B13: =+'bid input'!B7 -> 1104138 | C13: =+'bid input'!H7 -> 0 | D13: =+'bid input'!I7 -> 0 | E13: =+IF('bid input'!O7=1,"Y","N") -> N | F13: =+'bid input'!K7 | G13: =+IF(AND(IsSC="Y",LoanN_SC=LoanNumber,LoanN_SC>0),S_Percent,IF(AND(IsSC="Y",S_MO=MO,LoanN_SC=0),S_Percent,0))*LoanAmount -> 0 | H13: =+IF(AND(IsSC="Y",LoanN_SC=LoanNumber,LoanN_SC>0),S_Percent,IF(AND(IsSC="Y",S_MO=MO,LoanN_SC=0),S_Percent,0))*LoanAmount -> 0 | I13: =+IF(AND(IsSC="Y",LoanN_SC=LoanNumber,LoanN_SC>0),S_Percent,IF(AND(IsSC="Y",S_MO=MO,LoanN_SC=0),S_Percent,0))*LoanAmount -> 0 | J13: =+IF(AND(IsSC="Y",LoanN_SC=LoanNumber,LoanN_SC>0),S_Percent,IF(AND(IsSC="Y",S_MO=MO,LoanN_SC=0),S_Percent,0))*LoanAmount -> 0 | K13: =+IF(AND(IsSC="Y",LoanN_SC=LoanNumber,LoanN_SC>0),S_Percent,IF(AND(IsSC="Y",S_MO=MO,LoanN_SC=0),S_Percent,0))*LoanAmount -> 0 | L13: =+IF(AND(IsSC="Y",LoanN_SC=LoanNumber,LoanN_SC>0),S_Percent,IF(AND(IsSC="Y",S_MO=MO,LoanN_SC=0),S_Percent,0))*LoanAmount -> 0 | M13: =SUM(G13:L13) -> 0 | N13: ='bid input'!F7
B14: =+'bid input'!B8 -> 1104139 | C14: =+'bid input'!H8 -> 0 | D14: =+'bid input'!I8 -> 0 | E14: =+IF('bid input'!O8=1,"Y","N") -> N | F14: =+'bid input'!K8 | G14: =+IF(AND(IsSC="Y",LoanN_SC=LoanNumber,LoanN_SC>0),S_Percent,IF(AND(IsSC="Y",S_MO=MO,LoanN_SC=0),S_Percent,0))*LoanAmount -> 0 | H14: =+IF(AND(IsSC="Y",LoanN_SC=LoanNumber,LoanN_SC>0),S_Percent,IF(AND(IsSC="Y",S_MO=MO,LoanN_SC=0),S_Percent,0))*LoanAmount -> 0 | I14: =+IF(AND(IsSC="Y",LoanN_SC=LoanNumber,LoanN_SC>0),S_Percent,IF(AND(IsSC="Y",S_MO=MO,LoanN_SC=0),S_Percent,0))*LoanAmount -> 0 | J14: =+IF(AND(IsSC="Y",LoanN_SC=LoanNumber,LoanN_SC>0),S_Percent,IF(AND(IsSC="Y",S_MO=MO,LoanN_SC=0),S_Percent,0))*LoanAmount -> 0 | K14: =+IF(AND(IsSC="Y",LoanN_SC=LoanNumber,LoanN_SC>0),S_Percent,IF(AND(IsSC="Y",S_MO=MO,LoanN_SC=0),S_Percent,0))*LoanAmount -> 0 | L14: =+IF(AND(IsSC="Y",LoanN_SC=LoanNumber,LoanN_SC>0),S_Percent,IF(AND(IsSC="Y",S_MO=MO,LoanN_SC=0),S_Percent,0))*LoanAmount -> 0 | M14: =SUM(G14:L14) -> 0 | N14: ='bid input'!F8
B15: =+'bid input'!B9 -> 1104140 | C15: =+'bid input'!H9 -> 5 | D15: =+'bid input'!I9 -> 0 | E15: =+IF('bid input'!O9=1,"Y","N") -> Y | F15: =+'bid input'!K9 | G15: =+IF(AND(IsSC="Y",LoanN_SC=LoanNumber,LoanN_SC>0),S_Percent,IF(AND(IsSC="Y",S_MO=MO,LoanN_SC=0),S_Percent,0))*LoanAmount -> 0 | H15: =+IF(AND(IsSC="Y",LoanN_SC=LoanNumber,LoanN_SC>0),S_Percent,IF(AND(IsSC="Y",S_MO=MO,LoanN_SC=0),S_Percent,0))*LoanAmount -> 0 | I15: =+IF(AND(IsSC="Y",LoanN_SC=LoanNumber,LoanN_SC>0),S_Percent,IF(AND(IsSC="Y",S_MO=MO,LoanN_SC=0),S_Percent,0))*LoanAmount -> 0 | J15: =+IF(AND(IsSC="Y",LoanN_SC=LoanNumber,LoanN_SC>0),S_Percent,IF(AND(IsSC="Y",S_MO=MO,LoanN_SC=0),S_Percent,0))*LoanAmount -> 0 | K15: =+IF(AND(IsSC="Y",LoanN_SC=LoanNumber,LoanN_SC>0),S_Percent,IF(AND(IsSC="Y",S_MO=MO,LoanN_SC=0),S_Percent,0))*LoanAmount -> 103085 | L15: =+IF(AND(IsSC="Y",LoanN_SC=LoanNumber,LoanN_SC>0),S_Percent,IF(AND(IsSC="Y",S_MO=MO,LoanN_SC=0),S_Percent,0))*LoanAmount -> 0 | M15: =SUM(G15:L15) -> 103085 | N15: ='bid input'!F9
B16: =+'bid input'!B10 -> 1104141 | C16: =+'bid input'!H10 -> 0 | D16: =+'bid input'!I10 -> 0 | E16: =+IF('bid input'!O10=1,"Y","N") -> N | F16: =+'bid input'!K10 | G16: =+IF(AND(IsSC="Y",LoanN_SC=LoanNumber,LoanN_SC>0),S_Percent,IF(AND(IsSC="Y",S_MO=MO,LoanN_SC=0),S_Percent,0))*LoanAmount -> 0 | H16: =+IF(AND(IsSC="Y",LoanN_SC=LoanNumber,LoanN_SC>0),S_Percent,IF(AND(IsSC="Y",S_MO=MO,LoanN_SC=0),S_Percent,0))*LoanAmount -> 0 | I16: =+IF(AND(IsSC="Y",LoanN_SC=LoanNumber,LoanN_SC>0),S_Percent,IF(AND(IsSC="Y",S_MO=MO,LoanN_SC=0),S_Percent,0))*LoanAmount -> 0 | J16: =+IF(AND(IsSC="Y",LoanN_SC=LoanNumber,LoanN_SC>0),S_Percent,IF(AND(IsSC="Y",S_MO=MO,LoanN_SC=0),S_Percent,0))*LoanAmount -> 0 | K16: =+IF(AND(IsSC="Y",LoanN_SC=LoanNumber,LoanN_SC>0),S_Percent,IF(AND(IsSC="Y",S_MO=MO,LoanN_SC=0),S_Percent,0))*LoanAmount -> 0 | L16: =+IF(AND(IsSC="Y",LoanN_SC=LoanNumber,LoanN_SC>0),S_Percent,IF(AND(IsSC="Y",S_MO=MO,LoanN_SC=0),S_Percent,0))*LoanAmount -> 0 | M16: =SUM(G16:L16) -> 0 | N16: ='bid input'!F10
B17: =+'bid input'!B11 -> 1104159 | C17: =+'bid input'!H11 -> 1 | D17: =+'bid input'!I11 -> 0 | E17: =+IF('bid input'!O11=1,"Y","N") -> N | F17: =+'bid input'!K11 | G17: =+IF(AND(IsSC="Y",LoanN_SC=LoanNumber,LoanN_SC>0),S_Percent,IF(AND(IsSC="Y",S_MO=MO,LoanN_SC=0),S_Percent,0))*LoanAmount -> 0 | H17: =+IF(AND(IsSC="Y",LoanN_SC=LoanNumber,LoanN_SC>0),S_Percent,IF(AND(IsSC="Y",S_MO=MO,LoanN_SC=0),S_Percent,0))*LoanAmount -> 0 | I17: =+IF(AND(IsSC="Y",LoanN_SC=LoanNumber,LoanN_SC>0),S_Percent,IF(AND(IsSC="Y",S_MO=MO,LoanN_SC=0),S_Percent,0))*LoanAmount -> 0 | J17: =+IF(AND(IsSC="Y",LoanN_SC=LoanNumber,LoanN_SC>0),S_Percent,IF(AND(IsSC="Y",S_MO=MO,LoanN_SC=0),S_Percent,0))*LoanAmount -> 0 | K17: =+IF(AND(IsSC="Y",LoanN_SC=LoanNumber,LoanN_SC>0),S_Percent,IF(AND(IsSC="Y",S_MO=MO,LoanN_SC=0),S_Percent,0))*LoanAmount -> 0 | L17: =+IF(AND(IsSC="Y",LoanN_SC=LoanNumber,LoanN_SC>0),S_Percent,IF(AND(IsSC="Y",S_MO=MO,LoanN_SC=0),S_Percent,0))*LoanAmount -> 0 | M17: =SUM(G17:L17) -> 0 | N17: ='bid input'!F11
B18: =+'bid input'!B12 -> 1104161 | C18: =+'bid input'!H12 -> 4 | D18: =+'bid input'!I12 -> 0 | E18: =+IF('bid input'!O12=1,"Y","N") -> N | F18: =+'bid input'!K12 | G18: =+IF(AND(IsSC="Y",LoanN_SC=LoanNumber,LoanN_SC>0),S_Percent,IF(AND(IsSC="Y",S_MO=MO,LoanN_SC=0),S_Percent,0))*LoanAmount -> 0 | H18: =+IF(AND(IsSC="Y",LoanN_SC=LoanNumber,LoanN_SC>0),S_Percent,IF(AND(IsSC="Y",S_MO=MO,LoanN_SC=0),S_Percent,0))*LoanAmount -> 0 | I18: =+IF(AND(IsSC="Y",LoanN_SC=LoanNumber,LoanN_SC>0),S_Percent,IF(AND(IsSC="Y",S_MO=MO,LoanN_SC=0),S_Percent,0))*LoanAmount -> 0 | J18: =+IF(AND(IsSC="Y",LoanN_SC=LoanNumber,LoanN_SC>0),S_Percent,IF(AND(IsSC="Y",S_MO=MO,LoanN_SC=0),S_Percent,0))*LoanAmount -> 0 | K18: =+IF(AND(IsSC="Y",LoanN_SC=LoanNumber,LoanN_SC>0),S_Percent,IF(AND(IsSC="Y",S_MO=MO,LoanN_SC=0),S_Percent,0))*LoanAmount -> 0 | L18: =+IF(AND(IsSC="Y",LoanN_SC=LoanNumber,LoanN_SC>0),S_Percent,IF(AND(IsSC="Y",S_MO=MO,LoanN_SC=0),S_Percent,0))*LoanAmount -> 0 | M18: =SUM(G18:L18) -> 0 | N18: ='bid input'!F12
B19: =+'bid input'!B13 -> 1104145 | C19: =+'bid input'!H13 -> 1 | D19: =+'bid input'!I13 -> 0 | E19: =+IF('bid input'!O13=1,"Y","N") -> Y | F19: =+'bid input'!K13 | G19: =+IF(AND(IsSC="Y",LoanN_SC=LoanNumber,LoanN_SC>0),S_Percent,IF(AND(IsSC="Y",S_MO=MO,LoanN_SC=0),S_Percent,0))*LoanAmount -> 31872.5 | H19: =+IF(AND(IsSC="Y",LoanN_SC=LoanNumber,LoanN_SC>0),S_Percent,IF(AND(IsSC="Y",S_MO=MO,LoanN_SC=0),S_Percent,0))*LoanAmount -> 0 | I19: =+IF(AND(IsSC="Y",LoanN_SC=LoanNumber,LoanN_SC>0),S_Percent,IF(AND(IsSC="Y",S_MO=MO,LoanN_SC=0),S_Percent,0))*LoanAmount -> 0 | J19: =+IF(AND(IsSC="Y",LoanN_SC=LoanNumber,LoanN_SC>0),S_Percent,IF(AND(IsSC="Y",S_MO=MO,LoanN_SC=0),S_Percent,0))*LoanAmount -> 0 | K19: =+IF(AND(IsSC="Y",LoanN_SC=LoanNumber,LoanN_SC>0),S_Percent,IF(AND(IsSC="Y",S_MO=MO,LoanN_SC=0),S_Percent,0))*LoanAmount -> 0 | L19: =+IF(AND(IsSC="Y",LoanN_SC=LoanNumber,LoanN_SC>0),S_Percent,IF(AND(IsSC="Y",S_MO=MO,LoanN_SC=0),S_Percent,0))*LoanAmount -> 0 | M19: =SUM(G19:L19) -> 31872.5 | N19: ='bid input'!F13
... B27: =+'bid input'!B21 -> 1104158 | C27: =+'bid input'!H21 -> 1 | D27: =+'bid input'!I21 -> 0 | E27: =+IF('bid input'!O21=1,"Y","N") -> Y | F27: =+'bid input'!K21 | G27: =+IF(AND(IsSC="Y",LoanN_SC=LoanNumber,LoanN_SC>0),S_Percent,IF(AND(IsSC="Y",S_MO=MO,LoanN_SC=0),S_Percent,0))*LoanAmount -> 63745 | H27: =+IF(AND(IsSC="Y",LoanN_SC=LoanNumber,LoanN_SC>0),S_Percent,IF(AND(IsSC="Y",S_MO=MO,LoanN_SC=0),S_Percent,0))*LoanAmount -> 0 | I27: =+IF(AND(IsSC="Y",LoanN_SC=LoanNumber,LoanN_SC>0),S_Percent,IF(AND(IsSC="Y",S_MO=MO,LoanN_SC=0),S_Percent,0))*LoanAmount -> 0 | J27: =+IF(AND(IsSC="Y",LoanN_SC=LoanNumber,LoanN_SC>0),S_Percent,IF(AND(IsSC="Y",S_MO=MO,LoanN_SC=0),S_Percent,0))*LoanAmount -> 0 | K27: =+IF(AND(IsSC="Y",LoanN_SC=LoanNumber,LoanN_SC>0),S_Percent,IF(AND(IsSC="Y",S_MO=MO,LoanN_SC=0),S_Percent,0))*LoanAmount -> 0 | L27: =+IF(AND(IsSC="Y",LoanN_SC=LoanNumber,LoanN_SC>0),S_Percent,IF(AND(IsSC="Y",S_MO=MO,LoanN_SC=0),S_Percent,0))*LoanAmount -> 0 | M27: =SUM(G27:L27) -> 63745 | N27: ='bid input'!F21
B29: =+'bid input'!B2 -> 1104134 | F29: =+'bid input'!K2 | G29: =IF($M8<'bid input'!$M2,G8, 'bid input'!$M2*G8/$M8) -> 0 | H29: =IF($M8<'bid input'!$M2,H8, 'bid input'!$M2*H8/$M8) -> 0 | I29: =IF($M8<'bid input'!$M2,I8, 'bid input'!$M2*I8/$M8) -> 0 | J29: =IF($M8<'bid input'!$M2,J8, 'bid input'!$M2*J8/$M8) -> 0 | K29: =IF($M8<'bid input'!$M2,K8, 'bid input'!$M2*K8/$M8) -> 0 | L29: =IF($M8<'bid input'!$M2,L8, 'bid input'!$M2*L8/$M8) -> 0 | M29: =SUM(G29:L29) -> 0
B30: =+'bid input'!B3 -> 1104143 | F30: =+'bid input'!K3 | G30: =IF($M9<'bid input'!$M3,G9, 'bid input'!$M3*G9/$M9) -> 0 | H30: =IF($M9<'bid input'!$M3,H9, 'bid input'!$M3*H9/$M9) -> 0 | I30: =IF($M9<'bid input'!$M3,I9, 'bid input'!$M3*I9/$M9) -> 0 | J30: =IF($M9<'bid input'!$M3,J9, 'bid input'!$M3*J9/$M9) -> 0 | K30: =IF($M9<'bid input'!$M3,K9, 'bid input'!$M3*K9/$M9) -> 0 | L30: =IF($M9<'bid input'!$M3,L9, 'bid input'!$M3*L9/$M9) -> 0 | M30: =SUM(G30:L30) -> 0
B31: =+'bid input'!B4 -> 1104154 | F31: =+'bid input'!K4 | G31: =IF($M10<'bid input'!$M4,G10, 'bid input'!$M4*G10/$M10) -> 0 | H31: =IF($M10<'bid input'!$M4,H10, 'bid input'!$M4*H10/$M10) -> 0 | I31: =IF($M10<'bid input'!$M4,I10, 'bid input'!$M4*I10/$M10) -> 0 | J31: =IF($M10<'bid input'!$M4,J10, 'bid input'!$M4*J10/$M10) -> 0 | K31: =IF($M10<'bid input'!$M4,K10, 'bid input'!$M4*K10/$M10) -> 0 | L31: =IF($M10<'bid input'!$M4,L10, 'bid input'!$M4*L10/$M10) -> 0 | M31: =SUM(G31:L31) -> 0
B32: =+'bid input'!B5 -> 1104152 | F32: =+'bid input'!K5 | G32: =IF($M11<'bid input'!$M5,G11, 'bid input'!$M5*G11/$M11) -> 0 | H32: =IF($M11<'bid input'!$M5,H11, 'bid input'!$M5*H11/$M11) -> 0 | I32: =IF($M11<'bid input'!$M5,I11, 'bid input'!$M5*I11/$M11) -> 95975 | J32: =IF($M11<'bid input'!$M5,J11, 'bid input'!$M5*J11/$M11) -> 105080 | K32: =IF($M11<'bid input'!$M5,K11, 'bid input'!$M5*K11/$M11) -> 0 | L32: =IF($M11<'bid input'!$M5,L11, 'bid input'!$M5*L11/$M11) -> 0 | M32: =SUM(G32:L32) -> 201055
B33: =+'bid input'!B6 -> 1104136 | F33: =+'bid input'!K6 | G33: =IF($M12<'bid input'!$M6,G12, 'bid input'!$M6*G12/$M12) -> 0 | H33: =IF($M12<'bid input'!$M6,H12, 'bid input'!$M6*H12/$M12) -> 0 | I33: =IF($M12<'bid input'!$M6,I12, 'bid input'!$M6*I12/$M12) -> 0 | J33: =IF($M12<'bid input'!$M6,J12, 'bid input'!$M6*J12/$M12) -> 105080 | K33: =IF($M12<'bid input'!$M6,K12, 'bid input'!$M6*K12/$M12) -> 0 | L33: =IF($M12<'bid input'!$M6,L12, 'bid input'!$M6*L12/$M12) -> 0 | M33: =SUM(G33:L33) -> 105080
B34: =+'bid input'!B7 -> 1104138 | F34: =+'bid input'!K7 | G34: =IF($M13<'bid input'!$M7,G13, 'bid input'!$M7*G13/$M13) -> 0 | H34: =IF($M13<'bid input'!$M7,H13, 'bid input'!$M7*H13/$M13) -> 0 | I34: =IF($M13<'bid input'!$M7,I13, 'bid input'!$M7*I13/$M13) -> 0 | J34: =IF($M13<'bid input'!$M7,J13, 'bid input'!$M7*J13/$M13) -> 0 | K34: =IF($M13<'bid input'!$M7,K13, 'bid input'!$M7*K13/$M13) -> 0 | L34: =IF($M13<'bid input'!$M7,L13, 'bid input'!$M7*L13/$M13) -> 0 | M34: =SUM(G34:L34) -> 0
B35: =+'bid input'!B8 -> 1104139 | F35: =+'bid input'!K8 | G35: =IF($M14<'bid input'!$M8,G14, 'bid input'!$M8*G14/$M14) -> 0 | H35: =IF($M14<'bid input'!$M8,H14, 'bid input'!$M8*H14/$M14) -> 0 | I35: =IF($M14<'bid input'!$M8,I14, 'bid input'!$M8*I14/$M14) -> 0 | J35: =IF($M14<'bid input'!$M8,J14, 'bid input'!$M8*J14/$M14) -> 0 | K35: =IF($M14<'bid input'!$M8,K14, 'bid input'!$M8*K14/$M14) -> 0 | L35: =IF($M14<'bid input'!$M8,L14, 'bid input'!$M8*L14/$M14) -> 0 | M35: =SUM(G35:L35) -> 0
B36: =+'bid input'!B9 -> 1104140 | F36: =+'bid input'!K9 | G36: =IF($M15<'bid input'!$M9,G15, 'bid input'!$M9*G15/$M15) -> 0 | H36: =IF($M15<'bid input'!$M9,H15, 'bid input'!$M9*H15/$M15) -> 0 | I36: =IF($M15<'bid input'!$M9,I15, 'bid input'!$M9*I15/$M15) -> 0 | J36: =IF($M15<'bid input'!$M9,J15, 'bid input'!$M9*J15/$M15) -> 0 | K36: =IF($M15<'bid input'!$M9,K15, 'bid input'!$M9*K15/$M15) -> 74000 | L36: =IF($M15<'bid input'!$M9,L15, 'bid input'!$M9*L15/$M15) -> 0 | M36: =SUM(G36:L36) -> 74000
B37: =+'bid input'!B10 -> 1104141 | F37: =+'bid input'!K10 | G37: =IF($M16<'bid input'!$M10,G16, 'bid input'!$M10*G16/$M16) -> 0 | H37: =IF($M16<'bid input'!$M10,H16, 'bid input'!$M10*H16/$M16) -> 0 | I37: =IF($M16<'bid input'!$M10,I16, 'bid input'!$M10*I16/$M16) -> 0 | J37: =IF($M16<'bid input'!$M10,J16, 'bid input'!$M10*J16/$M16) -> 0 | K37: =IF($M16<'bid input'!$M10,K16, 'bid input'!$M10*K16/$M16) -> 0 | L37: =IF($M16<'bid input'!$M10,L16, 'bid input'!$M10*L16/$M16) -> 0 | M37: =SUM(G37:L37) -> 0
B38: =+'bid input'!B11 -> 1104159 | F38: =+'bid input'!K11 | G38: =IF($M17<'bid input'!$M11,G17, 'bid input'!$M11*G17/$M17) -> 0 | H38: =IF($M17<'bid input'!$M11,H17, 'bid input'!$M11*H17/$M17) -> 0 | I38: =IF($M17<'bid input'!$M11,I17, 'bid input'!$M11*I17/$M17) -> 0 | J38: =IF($M17<'bid input'!$M11,J17, 'bid input'!$M11*J17/$M17) -> 0 | K38: =IF($M17<'bid input'!$M11,K17, 'bid input'!$M11*K17/$M17) -> 0 | L38: =IF($M17<'bid input'!$M11,L17, 'bid input'!$M11*L17/$M17) -> 0 | M38: =SUM(G38:L38) -> 0
B39: =+'bid input'!B12 -> 1104161 | F39: =+'bid input'!K12 | G39: =IF($M18<'bid input'!$M12,G18, 'bid input'!$M12*G18/$M18) -> 0 | H39: =IF($M18<'bid input'!$M12,H18, 'bid input'!$M12*H18/$M18) -> 0 | I39: =IF($M18<'bid input'!$M12,I18, 'bid input'!$M12*I18/$M18) -> 0 | J39: =IF($M18<'bid input'!$M12,J18, 'bid input'!$M12*J18/$M18) -> 0 | K39: =IF($M18<'bid input'!$M12,K18, 'bid input'!$M12*K18/$M18) -> 0 | L39: =IF($M18<'bid input'!$M12,L18, 'bid input'!$M12*L18/$M18) -> 0 | M39: =SUM(G39:L39) -> 0
B40: =+'bid input'!B13 -> 1104145 | F40: =+'bid input'!K13 | G40: =IF($M19<'bid input'!$M13,G19, 'bid input'!$M13*G19/$M19) -> 31872.5 | H40: =IF($M19<'bid input'!$M13,H19, 'bid input'!$M13*H19/$M19) -> 0 | I40: =IF($M19<'bid input'!$M13,I19, 'bid input'!$M13*I19/$M19) -> 0 | J40: =IF($M19<'bid input'!$M13,J19, 'bid input'!$M13*J19/$M19) -> 0 | K40: =IF($M19<'bid input'!$M13,K19, 'bid input'!$M13*K19/$M19) -> 0 | L40: =IF($M19<'bid input'!$M13,L19, 'bid input'!$M13*L19/$M19) -> 0 | M40: =SUM(G40:L40) -> 31872.5
... B48: =+'bid input'!B21 -> 1104158 | F48: =+'bid input'!K21 | G48: =IF($M27<'bid input'!$M21,G27, 'bid input'!$M21*G27/$M27) -> 63745 | H48: =IF($M27<'bid input'!$M21,H27, 'bid input'!$M21*H27/$M27) -> 0 | I48: =IF($M27<'bid input'!$M21,I27, 'bid input'!$M21*I27/$M27) -> 0 | J48: =IF($M27<'bid input'!$M21,J27, 'bid input'!$M21*J27/$M27) -> 0 | K48: =IF($M27<'bid input'!$M21,K27, 'bid input'!$M21*K27/$M27) -> 0 | L48: =IF($M27<'bid input'!$M21,L27, 'bid input'!$M21*L27/$M27) -> 0 | M48: =SUM(G48:L48) -> 63745
D50: Total Specified/Competitive | G50: =SUM(G29:G49) -> 95617.5 | H50: =SUM(H29:H49) -> 0 | I50: =SUM(I29:I49) -> 95975 | J50: =SUM(J29:J49) -> 315240 | K50: =SUM(K29:K49) -> 177085 | L50: =SUM(L29:L49) -> 0 | M50: =SUM(G50:L50) -> 683917.5
D51: WA Rate | G51: =+IF(G50>0,SUMPRODUCT($F$29:$F$48,G$29:G$48)/G$50,"") -> 0.02 | H51: =+IF(H50>0,SUMPRODUCT($F$29:$F$48,H$29:H$48)/H$50,"") | I51: =+IF(I50>0,SUMPRODUCT($F$29:$F$48,I$29:I$48)/I$50,"") -> 0.03 | J51: =+IF(J50>0,SUMPRODUCT($F$29:$F$48,J$29:J$48)/J$50,"") -> 0.043333333 | K51: =+IF(K50>0,SUMPRODUCT($F$29:$F$48,K$29:K$48)/K$50,"") -> 0.022817044 | L51: =+IF(L50>0,SUMPRODUCT($F$29:$F$48,L$29:L$48)/L$50,"") | M51: =+SUMPRODUCT(G50:L50,G51:L51)/M50 -> 0.032887821
D53: Remaining need | G53: =+G4-G50 -> 223107.5 | H53: =+H4-H50 -> 375685 | I53: =+I4-I50 -> 383900 | J53: =+J4-J50 -> 210160 | K53: =+K4-K50 -> 338340 | L53: =+L4-L50 -> 485000 | M53: =SUM(G53:L53) -> 2016192.5
D54: Over(under)subscribed | G54: =+IF(G53=0,"NA",IF(G53<0,"OVER","UNDER")) -> UNDER | H54: =+IF(H53=0,"NA",IF(H53<0,"OVER","UNDER")) -> UNDER | I54: =+IF(I53=0,"NA",IF(I53<0,"OVER","UNDER")) -> UNDER | J54: =+IF(J53=0,"NA",IF(J53<0,"OVER","UNDER")) -> UNDER | K54: =+IF(K53=0,"NA",IF(K53<0,"OVER","UNDER")) -> UNDER | L54: =+IF(L53=0,"NA",IF(L53<0,"OVER","UNDER")) -> UNDER | M54: =+IF(M53=0,"NA",IF(M53<0,"OVER","UNDER")) -> UNDER
A56: Step 3 of process - Assets are assigned Specified/Non Competitive bids:
B57: Bid ID | C57: Loan # | D57: MO | E57: Specific & NonCompetitive? | F57: Rate >> | G57: 0.035 | H57: =+G57 | I57: =+H57 | J57: =+I57 | K57: =+J57 | L57: =+K57
B58: =+B8 -> 1104134 | C58: =+C8 -> 0 | D58: =+D8 -> 0 | E58: =+IF('bid input'!P2=1,"Y","N") -> N | G58: =+IF(AND(IsSNC="Y",LoanN_SNC=LoanNumber,LoanN_SNC>0),SN_Percent,IF(AND(IsSNC="Y",SN_MO=MO,LoanN_SNC=0),SN_Percent,0))*LoanAmount -> 0 | H58: =+IF(AND(IsSNC="Y",LoanN_SNC=LoanNumber,LoanN_SNC>0),SN_Percent,IF(AND(IsSNC="Y",SN_MO=MO,LoanN_SNC=0),SN_Percent,0))*LoanAmount -> 0 | I58: =+IF(AND(IsSNC="Y",LoanN_SNC=LoanNumber,LoanN_SNC>0),SN_Percent,IF(AND(IsSNC="Y",SN_MO=MO,LoanN_SNC=0),SN_Percent,0))*LoanAmount -> 0 | J58: =+IF(AND(IsSNC="Y",LoanN_SNC=LoanNumber,LoanN_SNC>0),SN_Percent,IF(AND(IsSNC="Y",SN_MO=MO,LoanN_SNC=0),SN_Percent,0))*LoanAmount -> 0 | K58: =+IF(AND(IsSNC="Y",LoanN_SNC=LoanNumber,LoanN_SNC>0),SN_Percent,IF(AND(IsSNC="Y",SN_MO=MO,LoanN_SNC=0),SN_Percent,0))*LoanAmount -> 0 | L58: =+IF(AND(IsSNC="Y",LoanN_SNC=LoanNumber,LoanN_SNC>0),SN_Percent,IF(AND(IsSNC="Y",SN_MO=MO,LoanN_SNC=0),SN_Percent,0))*LoanAmount -> 0 | M58: =SUM(G58:L58) -> 0 | N58: =N8
B59: =+B9 -> 1104143 | C59: =+C9 -> 0 | D59: =+D9 -> ABC Mortgage | E59: =+IF('bid input'!P3=1,"Y","N") -> Y | G59: =+IF(AND(IsSNC="Y",LoanN_SNC=LoanNumber,LoanN_SNC>0),SN_Percent,IF(AND(IsSNC="Y",SN_MO=MO,LoanN_SNC=0),SN_Percent,0))*LoanAmount -> 63745 | H59: =+IF(AND(IsSNC="Y",LoanN_SNC=LoanNumber,LoanN_SNC>0),SN_Percent,IF(AND(IsSNC="Y",SN_MO=MO,LoanN_SNC=0),SN_Percent,0))*LoanAmount -> 75137 | I59: =+IF(AND(IsSNC="Y",LoanN_SNC=LoanNumber,LoanN_SNC>0),SN_Percent,IF(AND(IsSNC="Y",SN_MO=MO,LoanN_SNC=0),SN_Percent,0))*LoanAmount -> 0 | J59: =+IF(AND(IsSNC="Y",LoanN_SNC=LoanNumber,LoanN_SNC>0),SN_Percent,IF(AND(IsSNC="Y",SN_MO=MO,LoanN_SNC=0),SN_Percent,0))*LoanAmount -> 0 | K59: =+IF(AND(IsSNC="Y",LoanN_SNC=LoanNumber,LoanN_SNC>0),SN_Percent,IF(AND(IsSNC="Y",SN_MO=MO,LoanN_SNC=0),SN_Percent,0))*LoanAmount -> 0 | L59: =+IF(AND(IsSNC="Y",LoanN_SNC=LoanNumber,LoanN_SNC>0),SN_Percent,IF(AND(IsSNC="Y",SN_MO=MO,LoanN_SNC=0),SN_Percent,0))*LoanAmount -> 0 | M59: =SUM(G59:L59) -> 138882 | N59: =N9
...
