Workbook

Sheet bid input
A1: time | B1: bidID | C1: Bid Type | D1: if general: Aggregate $ | E1: if general, max % per asset | F1: if specified, bid % | G1: if specified, loan or MO | H1: Loan # if applicable | I1: MO if applicable | J1: order type | K1: if competitive, bid rate | L1: order timing | M1: Funds available | N1: If auto, date/time order placed | O1: Specified & Competitive | P1: Specified & Noncompetitive | Q1: General & Competitive | R1: General & Noncompetitive | S1: time
A2: 0.625 | B2: 1104134 | C2: Specified | F2: 0.2 | G2: Loan | H2: 1 | J2: Noncompetitive | L2: Auto | M2: 187500 | N2: 40892.537 | O2: =+IF(AND(C2="Specified",J2="Competitive"),1,0) -> 0 | P2: =+IF(AND(C2="Specified",J2="Noncompetitive"),1,0) -> 1 | Q2: =+IF(AND(C2="General",J2="Competitive"),1,0) -> 0 | R2: =+IF(AND(C2="General",J2="Noncompetitive"),1,0) -> 0 | S2: 40928.625
A3: 0.625 | B3: 1104143 | C3: Specified | F3: 0.2 | G3: MO | I3: ABC Mortgage | J3: Noncompetitive | L3: Auto | M3: 500000 | N3: 40897.364 | O3: =+IF(AND(C3="Specified",J3="Competitive"),1,0) -> 0 | P3: =+IF(AND(C3="Specified",J3="Noncompetitive"),1,0) -> 1 | Q3: =+IF(AND(C3="General",J3="Competitive"),1,0) -> 0 | R3: =+IF(AND(C3="General",J3="Noncompetitive"),1,0) -> 0 | S3: 40928.625
A4: 0.625 | B4: 1104154 | C4: Specified | F4: 0.2 | G4: Loan | H4: 2 | J4: Noncompetitive | L4: Auto | M4: 185000 | N4: 40913.387 | O4: =+IF(AND(C4="Specified",J4="Competitive"),1,0) -> 0 | P4: =+IF(AND(C4="Specified",J4="Noncompetitive"),1,0) -> 1 | Q4: =+IF(AND(C4="General",J4="Competitive"),1,0) -> 0 | R4: =+IF(AND(C4="General",J4="Noncompetitive"),1,0) -> 0 | S4: 40928.625
A5: 0.625 | B5: 1104152 | C5: Specified | F5: 0.2 | G5: MO | I5: Prime Lending | J5: Noncompetitive | L5: Auto | M5: 1500000 | N5: 40913.386 | O5: =+IF(AND(C5="Specified",J5="Competitive"),1,0) -> 0 | P5: =+IF(AND(C5="Specified",J5="Noncompetitive"),1,0) -> 1 | Q5: =+IF(AND(C5="General",J5="Competitive"),1,0) -> 0 | R5: =+IF(AND(C5="General",J5="Noncompetitive"),1,0) -> 0 | S5: 40928.625
A6: 0.71263889 | B6: 1104136 | C6: Specified | F6: 0.2 | G6: Loan | H6: 4 | J6: Noncompetitive | L6: Day Trade | M6: 860000 | O6: =+IF(AND(C6="Specified",J6="Competitive"),1,0) -> 0 | P6: =+IF(AND(C6="Specified",J6="Noncompetitive"),1,0) -> 1 | Q6: =+IF(AND(C6="General",J6="Competitive"),1,0) -> 0 | R6: =+IF(AND(C6="General",J6="Noncompetitive"),1,0) -> 0 | S6: 40928.713
A7: 0.77263889 | B7: 1104138 | C7: Specified | F7: 0.2 | G7: MO | I7: Best Loans Inc | J7: Noncompetitive | L7: Day Trade | M7: 300000 | O7: =+IF(AND(C7="Specified",J7="Competitive"),1,0) -> 0 | P7: =+IF(AND(C7="Specified",J7="Noncompetitive"),1,0) -> 1 | Q7: =+IF(AND(C7="General",J7="Competitive"),1,0) -> 0 | R7: =+IF(AND(C7="General",J7="Noncompetitive"),1,0) -> 0 | S7: 40928.773
A8: 0.80263889 | B8: 1104139 | C8: Specified | F8: 0.2 | G8: Loan | H8: 1 | J8: Noncompetitive | L8: Day Trade | M8: 250000 | O8: =+IF(AND(C8="Specified",J8="Competitive"),1,0) -> 0 | P8: =+IF(AND(C8="Specified",J8="Noncompetitive"),1,0) -> 1 | Q8: =+IF(AND(C8="General",J8="Competitive"),1,0) -> 0 | R8: =+IF(AND(C8="General",J8="Noncompetitive"),1,0) -> 0 | S8: 40928.803
A9: 0.83263889 | B9: 1104140 | C9: Specified | F9: 0.2 | G9: Loan | H9: 5 | J9: Noncompetitive | L9: Day Trade | M9: 74000 | O9: =+IF(AND(C9="Specified",J9="Competitive"),1,0) -> 0 | P9: =+IF(AND(C9="Specified",J9="Noncompetitive"),1,0) -> 1 | Q9: =+IF(AND(C9="General",J9="Competitive"),1,0) -> 0 | R9: =+IF(AND(C9="General",J9="Noncompetitive"),1,0) -> 0 | S9: 40928.833
A10: 0.86263889 | B10: 1104141 | C10: Specified | F10: 0.2 | G10: Loan | H10: 5 | J10: Noncompetitive | L10: Day Trade | M10: 285000 | O10: =+IF(AND(C10="Specified",J10="Competitive"),1,0) -> 0 | P10: =+IF(AND(C10="Specified",J10="Noncompetitive"),1,0) -> 1 | Q10: =+IF(AND(C10="General",J10="Competitive"),1,0) -> 0 | R10: =+IF(AND(C10="General",J10="Noncompetitive"),1,0) -> 0 | S10: 40928.863
A11: 0.90263889 | B11: 1104159 | C11: Specified | F11: 0.2 | G11: Loan | H11: 1 | J11: Noncompetitive | L11: Day Trade | M11: 532000 | O11: =+IF(AND(C11="Specified",J11="Competitive"),1,0) -> 0 | P11: =+IF(AND(C11="Specified",J11="Noncompetitive"),1,0) -> 1 | Q11: =+IF(AND(C11="General",J11="Competitive"),1,0) -> 0 | R11: =+IF(AND(C11="General",J11="Noncompetitive"),1,0) -> 0 | S11: 40928.903
A12: 0.96263889 | B12: 1104161 | C12: Specified | F12: 0.2 | G12: Loan | H12: 4 | J12: Noncompetitive | L12: Day Trade | M12: 292000 | O12: =+IF(AND(C12="Specified",J12="Competitive"),1,0) -> 0 | P12: =+IF(AND(C12="Specified",J12="Noncompetitive"),1,0) -> 1 | Q12: =+IF(AND(C12="General",J12="Competitive"),1,0) -> 0 | R12: =+IF(AND(C12="General",J12="Noncompetitive"),1,0) -> 0 | S12: 40928.963
A13: 0.98263889 | B13: 1104145 | C13: Specified | F13: 0.1 | G13: Loan | H13: 1 | J13: Noncompetitive | L13: Day Trade | M13: 752000 | O13: =+IF(AND(C13="Specified",J13="Competitive"),1,0) -> 0 | P13: =+IF(AND(C13="Specified",J13="Noncompetitive"),1,0) -> 1 | Q13: =+IF(AND(C13="General",J13="Competitive"),1,0) -> 0 | R13: =+IF(AND(C13="General",J13="Noncompetitive"),1,0) -> 0 | S13: 40928.983
A14: 1.0993056 | B14: 1104133 | C14: Specified | F14: 0.2 | G14: Loan | H14: 4 | J14: Noncompetitive | L14: Day Trade | M14: 418000 | O14: =+IF(AND(C14="Specified",J14="Competitive"),1,0) -> 0 | P14: =+IF(AND(C14="Specified",J14="Noncompetitive"),1,0) -> 1 | Q14: =+IF(AND(C14="General",J14="Competitive"),1,0) -> 0 | R14: =+IF(AND(C14="General",J14="Noncompetitive"),1,0) -> 0 | S14: 40929.099
A15: 1.1026389 | B15: 1104149 | C15: Specified | F15: 0.2 | G15: Loan | H15: 5 | J15: Noncompetitive | L15: Day Trade | M15: 47000 | O15: =+IF(AND(C15="Specified",J15="Competitive"),1,0) -> 0 | P15: =+IF(AND(C15="Specified",J15="Noncompetitive"),1,0) -> 1 | Q15: =+IF(AND(C15="General",J15="Competitive"),1,0) -> 0 | R15: =+IF(AND(C15="General",J15="Noncompetitive"),1,0) -> 0 | S15: 40929.103
A16: 1.1626389 | B16: 1104151 | C16: Specified | F16: 0.2 | G16: Loan | H16: 1 | J16: Noncompetitive | L16: Day Trade | M16: 283000 | O16: =+IF(AND(C16="Specified",J16="Competitive"),1,0) -> 0 | P16: =+IF(AND(C16="Specified",J16="Noncompetitive"),1,0) -> 1 | Q16: =+IF(AND(C16="General",J16="Competitive"),1,0) -> 0 | R16: =+IF(AND(C16="General",J16="Noncompetitive"),1,0) -> 0 | S16: 40929.163
A17: 1.1926389 | B17: 1104131 | C17: Specified | F17: 0.2 | G17: MO | H17: 4 | J17: Noncompetitive | L17: Day Trade | M17: 598000 | O17: =+IF(AND(C17="Specified",J17="Competitive"),1,0) -> 0 | P17: =+IF(AND(C17="Specified",J17="Noncompetitive"),1,0) -> 1 | Q17: =+IF(AND(C17="General",J17="Competitive"),1,0) -> 0 | R17: =+IF(AND(C17="General",J17="Noncompetitive"),1,0) -> 0 | S17: 40929.193
A18: 1.2826389 | B18: 1104155 | C18: Specified | F18: 0.2 | G18: MO | I18: Best Loans Inc | J18: Noncompetitive | L18: Day Trade | M18: 639000 | O18: =+IF(AND(C18="Specified",J18="Competitive"),1,0) -> 0 | P18: =+IF(AND(C18="Specified",J18="Noncompetitive"),1,0) -> 1 | Q18: =+IF(AND(C18="General",J18="Competitive"),1,0) -> 0 | R18: =+IF(AND(C18="General",J18="Noncompetitive"),1,0) -> 0 | S18: 40929.283
A19: 1.3126389 | B19: 1104156 | C19: Specified | F19: 0.2 | G19: Loan | H19: 2 | J19: Noncompetitive | L19: Day Trade | M19: 274000 | O19: =+IF(AND(C19="Specified",J19="Competitive"),1,0) -> 0 | P19: =+IF(AND(C19="Specified",J19="Noncompetitive"),1,0) -> 1 | Q19: =+IF(AND(C19="General",J19="Competitive"),1,0) -> 0 | R19: =+IF(AND(C19="General",J19="Noncompetitive"),1,0) -> 0 | S19: 40929.313
A20: 1.3426389 | B20: 1104157 | C20: Specified | F20: 0.2 | G20: Loan | I20: Best Loans Inc | J20: Noncompetitive | L20: Day Trade | M20: 629000 | O20: =+IF(AND(C20="Specified",J20="Competitive"),1,0) -> 0 | P20: =+IF(AND(C20="Specified",J20="Noncompetitive"),1,0) -> 1 | Q20: =+IF(AND(C20="General",J20="Competitive"),1,0) -> 0 | R20: =+IF(AND(C20="General",J20="Noncompetitive"),1,0) -> 0 | S20: 40929.343
A21: 1.3726389 | B21: 1104158 | C21: Specified | F21: 0.2 | G21: Loan | H21: 1 | J21: Noncompetitive | L21: Day Trade | M21: 562000 | O21: =+IF(AND(C21="Specified",J21="Competitive"),1,0) -> 0 | P21: =+IF(AND(C21="Specified",J21="Noncompetitive"),1,0) -> 1 | Q21: =+IF(AND(C21="General",J21="Competitive"),1,0) -> 0 | R21: =+IF(AND(C21="General",J21="Noncompetitive"),1,0) -> 0 | S21: 40929.373

Sheet assets available for bid
F1: Allocation process:
E2: Loan Number | G2: 1 | H2: 2 | I2: 3 | J2: 4 | K2: 5 | L2: 6 | M2: Batch Total
E3: MO | G3: ABC Mortgage | H3: ABC Mortgage | I3: Prime Lending | J3: Prime Lending | K3: Best Loans Inc | L3: Integrity Lending
E4: Loan Amount | G4: 318725 | H4: 375685 | I4: 479875 | J4: 525400 | K4: 515425 | L4: 485000 | M4: =SUM(G4:L4) -> 2700110
A6: Step 2 of process - Assets are assigned Specified/Competitive bids:
B7: Bid ID | C7: Loan # | D7: MO | E7: Specific & Competitive? | F7: Rate
B8: =+'bid input'!B2 -> 1104134 | C8: =+'bid input'!H2 -> 1 | D8: =+'bid input'!I2 -> 0 | E8: =+IF('bid input'!O2=1,"Y","N") -> N | F8: =+'bid input'!K2 -> 0 | G8: =+IF(AND($E8="Y",$C8=G$2,$C8>0),'bid input'!$F2,IF(AND($E8="Y",$D8=G$3,$C8=0),'bid input'!$F2,0))*G$4 -> 0 | H8: =+IF(AND($E8="Y",$C8=H$2,$C8>0),'bid input'!$F2,IF(AND($E8="Y",$D8=H$3,$C8=0),'bid input'!$F2,0))*H$4 -> 0 | I8: =+IF(AND($E8="Y",$C8=I$2,$C8>0),'bid input'!$F2,IF(AND($E8="Y",$D8=I$3,$C8=0),'bid input'!$F2,0))*I$4 -> 0 | J8: =+IF(AND($E8="Y",$C8=J$2,$C8>0),'bid input'!$F2,IF(AND($E8="Y",$D8=J$3,$C8=0),'bid input'!$F2,0))*J$4 -> 0 | K8: =+IF(AND($E8="Y",$C8=K$2,$C8>0),'bid input'!$F2,IF(AND($E8="Y",$D8=K$3,$C8=0),'bid input'!$F2,0))*K$4 -> 0 | L8: =+IF(AND($E8="Y",$C8=L$2,$C8>0),'bid input'!$F2,IF(AND($E8="Y",$D8=L$3,$C8=0),'bid input'!$F2,0))*L$4 -> 0 | M8: =SUM(G8:L8) -> 0
B9: =+'bid input'!B3 -> 1104143 | C9: =+'bid input'!H3 -> 0 | D9: =+'bid input'!I3 -> ABC Mortgage | E9: =+IF('bid input'!O3=1,"Y","N") -> N | F9: =+'bid input'!K3 -> 0 | G9: =+IF(AND($E9="Y",$C9=G$2,$C9>0),'bid input'!$F3,IF(AND($E9="Y",$D9=G$3,$C9=0),'bid input'!$F3,0))*G$4 -> 0 | H9: =+IF(AND($E9="Y",$C9=H$2,$C9>0),'bid input'!$F3,IF(AND($E9="Y",$D9=H$3,$C9=0),'bid input'!$F3,0))*H$4 -> 0 | I9: =+IF(AND($E9="Y",$C9=I$2,$C9>0),'bid input'!$F3,IF(AND($E9="Y",$D9=I$3,$C9=0),'bid input'!$F3,0))*I$4 -> 0 | J9: =+IF(AND($E9="Y",$C9=J$2,$C9>0),'bid input'!$F3,IF(AND($E9="Y",$D9=J$3,$C9=0),'bid input'!$F3,0))*J$4 -> 0 | K9: =+IF(AND($E9="Y",$C9=K$2,$C9>0),'bid input'!$F3,IF(AND($E9="Y",$D9=K$3,$C9=0),'bid input'!$F3,0))*K$4 -> 0 | L9: =+IF(AND($E9="Y",$C9=L$2,$C9>0),'bid input'!$F3,IF(AND($E9="Y",$D9=L$3,$C9=0),'bid input'!$F3,0))*L$4 -> 0 | M9: =SUM(G9:L9) -> 0
B10: =+'bid input'!B4 -> 1104154 | C10: =+'bid input'!H4 -> 2 | D10: =+'bid input'!I4 -> 0 | E10: =+IF('bid input'!O4=1,"Y","N") -> N | F10: =+'bid input'!K4 -> 0 | G10: =+IF(AND($E10="Y",$C10=G$2,$C10>0),'bid input'!$F4,IF(AND($E10="Y",$D10=G$3,$C10=0),'bid input'!$F4,0))*G$4 -> 0 | H10: =+IF(AND($E10="Y",$C10=H$2,$C10>0),'bid input'!$F4,IF(AND($E10="Y",$D10=H$3,$C10=0),'bid input'!$F4,0))*H$4 -> 0 | I10: =+IF(AND($E10="Y",$C10=I$2,$C10>0),'bid input'!$F4,IF(AND($E10="Y",$D10=I$3,$C10=0),'bid input'!$F4,0))*I$4 -> 0 | J10: =+IF(AND($E10="Y",$C10=J$2,$C10>0),'bid input'!$F4,IF(AND($E10="Y",$D10=J$3,$C10=0),'bid input'!$F4,0))*J$4 -> 0 | K10: =+IF(AND($E10="Y",$C10=K$2,$C10>0),'bid input'!$F4,IF(AND($E10="Y",$D10=K$3,$C10=0),'bid input'!$F4,0))*K$4 -> 0 | L10: =+IF(AND($E10="Y",$C10=L$2,$C10>0),'bid input'!$F4,IF(AND($E10="Y",$D10=L$3,$C10=0),'bid input'!$F4,0))*L$4 -> 0 | M10: =SUM(G10:L10) -> 0
B11: =+'bid input'!B5 -> 1104152 | C11: =+'bid input'!H5 -> 0 | D11: =+'bid input'!I5 -> Prime Lending | E11: =+IF('bid input'!O5=1,"Y","N") -> N | F11: =+'bid input'!K5 -> 0 | G11: =+IF(AND($E11="Y",$C11=G$2,$C11>0),'bid input'!$F5,IF(AND($E11="Y",$D11=G$3,$C11=0),'bid input'!$F5,0))*G$4 -> 0 | H11: =+IF(AND($E11="Y",$C11=H$2,$C11>0),'bid input'!$F5,IF(AND($E11="Y",$D11=H$3,$C11=0),'bid input'!$F5,0))*H$4 -> 0 | I11: =+IF(AND($E11="Y",$C11=I$2,$C11>0),'bid input'!$F5,IF(AND($E11="Y",$D11=I$3,$C11=0),'bid input'!$F5,0))*I$4 -> 0 | J11: =+IF(AND($E11="Y",$C11=J$2,$C11>0),'bid input'!$F5,IF(AND($E11="Y",$D11=J$3,$C11=0),'bid input'!$F5,0))*J$4 -> 0 | K11: =+IF(AND($E11="Y",$C11=K$2,$C11>0),'bid input'!$F5,IF(AND($E11="Y",$D11=K$3,$C11=0),'bid input'!$F5,0))*K$4 -> 0 | L11: =+IF(AND($E11="Y",$C11=L$2,$C11>0),'bid input'!$F5,IF(AND($E11="Y",$D11=L$3,$C11=0),'bid input'!$F5,0))*L$4 -> 0 | M11: =SUM(G11:L11) -> 0
B12: =+'bid input'!B6 -> 1104136 | C12: =+'bid input'!H6 -> 4 | D12: =+'bid input'!I6 -> 0 | E12: =+IF('bid input'!O6=1,"Y","N") -> N | F12: =+'bid input'!K6 -> 0 | G12: =+IF(AND($E12="Y",$C12=G$2,$C12>0),'bid input'!$F6,IF(AND($E12="Y",$D12=G$3,$C12=0),'bid input'!$F6,0))*G$4 -> 0 | H12: =+IF(AND($E12="Y",$C12=H$2,$C12>0),'bid input'!$F6,IF(AND($E12="Y",$D12=H$3,$C12=0),'bid input'!$F6,0))*H$4 -> 0 | I12: =+IF(AND($E12="Y",$C12=I$2,$C12>0),'bid input'!$F6,IF(AND($E12="Y",$D12=I$3,$C12=0),'bid input'!$F6,0))*I$4 -> 0 | J12: =+IF(AND($E12="Y",$C12=J$2,$C12>0),'bid input'!$F6,IF(AND($E12="Y",$D12=J$3,$C12=0),'bid input'!$F6,0))*J$4 -> 0 | K12: =+IF(AND($E12="Y",$C12=K$2,$C12>0),'bid input'!$F6,IF(AND($E12="Y",$D12=K$3,$C12=0),'bid input'!$F6,0))*K$4 -> 0 | L12: =+IF(AND($E12="Y",$C12=L$2,$C12>0),'bid input'!$F6,IF(AND($E12="Y",$D12=L$3,$C12=0),'bid input'!$F6,0))*L$4 -> 0 | M12: =SUM(G12:L12) -> 0
B13: =+'bid input'!B7 -> 1104138 | C13: =+'bid input'!H7 -> 0 | D13: =+'bid input'!I7 -> Best Loans Inc | E13: =+IF('bid input'!O7=1,"Y","N") -> N | F13: =+'bid input'!K7 -> 0 | G13: =+IF(AND($E13="Y",$C13=G$2,$C13>0),'bid input'!$F7,IF(AND($E13="Y",$D13=G$3,$C13=0),'bid input'!$F7,0))*G$4 -> 0 | H13: =+IF(AND($E13="Y",$C13=H$2,$C13>0),'bid input'!$F7,IF(AND($E13="Y",$D13=H$3,$C13=0),'bid input'!$F7,0))*H$4 -> 0 | I13: =+IF(AND($E13="Y",$C13=I$2,$C13>0),'bid input'!$F7,IF(AND($E13="Y",$D13=I$3,$C13=0),'bid input'!$F7,0))*I$4 -> 0 | J13: =+IF(AND($E13="Y",$C13=J$2,$C13>0),'bid input'!$F7,IF(AND($E13="Y",$D13=J$3,$C13=0),'bid input'!$F7,0))*J$4 -> 0 | K13: =+IF(AND($E13="Y",$C13=K$2,$C13>0),'bid input'!$F7,IF(AND($E13="Y",$D13=K$3,$C13=0),'bid input'!$F7,0))*K$4 -> 0 | L13: =+IF(AND($E13="Y",$C13=L$2,$C13>0),'bid input'!$F7,IF(AND($E13="Y",$D13=L$3,$C13=0),'bid input'!$F7,0))*L$4 -> 0 | M13: =SUM(G13:L13) -> 0
B14: =+'bid input'!B8 -> 1104139 | C14: =+'bid input'!H8 -> 1 | D14: =+'bid input'!I8 -> 0 | E14: =+IF('bid input'!O8=1,"Y","N") -> N | F14: =+'bid input'!K8 -> 0 | G14: =+IF(AND($E14="Y",$C14=G$2,$C14>0),'bid input'!$F8,IF(AND($E14="Y",$D14=G$3,$C14=0),'bid input'!$F8,0))*G$4 -> 0 | H14: =+IF(AND($E14="Y",$C14=H$2,$C14>0),'bid input'!$F8,IF(AND($E14="Y",$D14=H$3,$C14=0),'bid input'!$F8,0))*H$4 -> 0 | I14: =+IF(AND($E14="Y",$C14=I$2,$C14>0),'bid input'!$F8,IF(AND($E14="Y",$D14=I$3,$C14=0),'bid input'!$F8,0))*I$4 -> 0 | J14: =+IF(AND($E14="Y",$C14=J$2,$C14>0),'bid input'!$F8,IF(AND($E14="Y",$D14=J$3,$C14=0),'bid input'!$F8,0))*J$4 -> 0 | K14: =+IF(AND($E14="Y",$C14=K$2,$C14>0),'bid input'!$F8,IF(AND($E14="Y",$D14=K$3,$C14=0),'bid input'!$F8,0))*K$4 -> 0 | L14: =+IF(AND($E14="Y",$C14=L$2,$C14>0),'bid input'!$F8,IF(AND($E14="Y",$D14=L$3,$C14=0),'bid input'!$F8,0))*L$4 -> 0 | M14: =SUM(G14:L14) -> 0
B15: =+'bid input'!B9 -> 1104140 | C15: =+'bid input'!H9 -> 5 | D15: =+'bid input'!I9 -> 0 | E15: =+IF('bid input'!O9=1,"Y","N") -> N | F15: =+'bid input'!K9 -> 0 | G15: =+IF(AND($E15="Y",$C15=G$2,$C15>0),'bid input'!$F9,IF(AND($E15="Y",$D15=G$3,$C15=0),'bid input'!$F9,0))*G$4 -> 0 | H15: =+IF(AND($E15="Y",$C15=H$2,$C15>0),'bid input'!$F9,IF(AND($E15="Y",$D15=H$3,$C15=0),'bid input'!$F9,0))*H$4 -> 0 | I15: =+IF(AND($E15="Y",$C15=I$2,$C15>0),'bid input'!$F9,IF(AND($E15="Y",$D15=I$3,$C15=0),'bid input'!$F9,0))*I$4 -> 0 | J15: =+IF(AND($E15="Y",$C15=J$2,$C15>0),'bid input'!$F9,IF(AND($E15="Y",$D15=J$3,$C15=0),'bid input'!$F9,0))*J$4 -> 0 | K15: =+IF(AND($E15="Y",$C15=K$2,$C15>0),'bid input'!$F9,IF(AND($E15="Y",$D15=K$3,$C15=0),'bid input'!$F9,0))*K$4 -> 0 | L15: =+IF(AND($E15="Y",$C15=L$2,$C15>0),'bid input'!$F9,IF(AND($E15="Y",$D15=L$3,$C15=0),'bid input'!$F9,0))*L$4 -> 0 | M15: =SUM(G15:L15) -> 0
B16: =+'bid input'!B10 -> 1104141 | C16: =+'bid input'!H10 -> 5 | D16: =+'bid input'!I10 -> 0 | E16: =+IF('bid input'!O10=1,"Y","N") -> N | F16: =+'bid input'!K10 -> 0 | G16: =+IF(AND($E16="Y",$C16=G$2,$C16>0),'bid input'!$F10,IF(AND($E16="Y",$D16=G$3,$C16=0),'bid input'!$F10,0))*G$4 -> 0 | H16: =+IF(AND($E16="Y",$C16=H$2,$C16>0),'bid input'!$F10,IF(AND($E16="Y",$D16=H$3,$C16=0),'bid input'!$F10,0))*H$4 -> 0 | I16: =+IF(AND($E16="Y",$C16=I$2,$C16>0),'bid input'!$F10,IF(AND($E16="Y",$D16=I$3,$C16=0),'bid input'!$F10,0))*I$4 -> 0 | J16: =+IF(AND($E16="Y",$C16=J$2,$C16>0),'bid input'!$F10,IF(AND($E16="Y",$D16=J$3,$C16=0),'bid input'!$F10,0))*J$4 -> 0 | K16: =+IF(AND($E16="Y",$C16=K$2,$C16>0),'bid input'!$F10,IF(AND($E16="Y",$D16=K$3,$C16=0),'bid input'!$F10,0))*K$4 -> 0 | L16: =+IF(AND($E16="Y",$C16=L$2,$C16>0),'bid input'!$F10,IF(AND($E16="Y",$D16=L$3,$C16=0),'bid input'!$F10,0))*L$4 -> 0 | M16: =SUM(G16:L16) -> 0
B17: =+'bid input'!B11 -> 1104159 | C17: =+'bid input'!H11 -> 1 | D17: =+'bid input'!I11 -> 0 | E17: =+IF('bid input'!O11=1,"Y","N") -> N | F17: =+'bid input'!K11 -> 0 | G17: =+IF(AND($E17="Y",$C17=G$2,$C17>0),'bid input'!$F11,IF(AND($E17="Y",$D17=G$3,$C17=0),'bid input'!$F11,0))*G$4 -> 0 | H17: =+IF(AND($E17="Y",$C17=H$2,$C17>0),'bid input'!$F11,IF(AND($E17="Y",$D17=H$3,$C17=0),'bid input'!$F11,0))*H$4 -> 0 | I17: =+IF(AND($E17="Y",$C17=I$2,$C17>0),'bid input'!$F11,IF(AND($E17="Y",$D17=I$3,$C17=0),'bid input'!$F11,0))*I$4 -> 0 | J17: =+IF(AND($E17="Y",$C17=J$2,$C17>0),'bid input'!$F11,IF(AND($E17="Y",$D17=J$3,$C17=0),'bid input'!$F11,0))*J$4 -> 0 | K17: =+IF(AND($E17="Y",$C17=K$2,$C17>0),'bid input'!$F11,IF(AND($E17="Y",$D17=K$3,$C17=0),'bid input'!$F11,0))*K$4 -> 0 | L17: =+IF(AND($E17="Y",$C17=L$2,$C17>0),'bid input'!$F11,IF(AND($E17="Y",$D17=L$3,$C17=0),'bid input'!$F11,0))*L$4 -> 0 | M17: =SUM(G17:L17) -> 0
B18: =+'bid input'!B12 -> 1104161 | C18: =+'bid input'!H12 -> 4 | D18: =+'bid input'!I12 -> 0 | E18: =+IF('bid input'!O12=1,"Y","N") -> N | F18: =+'bid input'!K12 -> 0 | G18: =+IF(AND($E18="Y",$C18=G$2,$C18>0),'bid input'!$F12,IF(AND($E18="Y",$D18=G$3,$C18=0),'bid input'!$F12,0))*G$4 -> 0 | H18: =+IF(AND($E18="Y",$C18=H$2,$C18>0),'bid input'!$F12,IF(AND($E18="Y",$D18=H$3,$C18=0),'bid input'!$F12,0))*H$4 -> 0 | I18: =+IF(AND($E18="Y",$C18=I$2,$C18>0),'bid input'!$F12,IF(AND($E18="Y",$D18=I$3,$C18=0),'bid input'!$F12,0))*I$4 -> 0 | J18: =+IF(AND($E18="Y",$C18=J$2,$C18>0),'bid input'!$F12,IF(AND($E18="Y",$D18=J$3,$C18=0),'bid input'!$F12,0))*J$4 -> 0 | K18: =+IF(AND($E18="Y",$C18=K$2,$C18>0),'bid input'!$F12,IF(AND($E18="Y",$D18=K$3,$C18=0),'bid input'!$F12,0))*K$4 -> 0 | L18: =+IF(AND($E18="Y",$C18=L$2,$C18>0),'bid input'!$F12,IF(AND($E18="Y",$D18=L$3,$C18=0),'bid input'!$F12,0))*L$4 -> 0 | M18: =SUM(G18:L18) -> 0
B19: =+'bid input'!B13 -> 1104145 | C19: =+'bid input'!H13 -> 1 | D19: =+'bid input'!I13 -> 0 | E19: =+IF('bid input'!O13=1,"Y","N") -> N | F19: =+'bid input'!K13 -> 0 | G19: =+IF(AND($E19="Y",$C19=G$2,$C19>0),'bid input'!$F13,IF(AND($E19="Y",$D19=G$3,$C19=0),'bid input'!$F13,0))*G$4 -> 0 | H19: =+IF(AND($E19="Y",$C19=H$2,$C19>0),'bid input'!$F13,IF(AND($E19="Y",$D19=H$3,$C19=0),'bid input'!$F13,0))*H$4 -> 0 | I19: =+IF(AND($E19="Y",$C19=I$2,$C19>0),'bid input'!$F13,IF(AND($E19="Y",$D19=I$3,$C19=0),'bid input'!$F13,0))*I$4 -> 0 | J19: =+IF(AND($E19="Y",$C19=J$2,$C19>0),'bid input'!$F13,IF(AND($E19="Y",$D19=J$3,$C19=0),'bid input'!$F13,0))*J$4 -> 0 | K19: =+IF(AND($E19="Y",$C19=K$2,$C19>0),'bid input'!$F13,IF(AND($E19="Y",$D19=K$3,$C19=0),'bid input'!$F13,0))*K$4 -> 0 | L19: =+IF(AND($E19="Y",$C19=L$2,$C19>0),'bid input'!$F13,IF(AND($E19="Y",$D19=L$3,$C19=0),'bid input'!$F13,0))*L$4 -> 0 | M19: =SUM(G19:L19) -> 0
... B27: =+'bid input'!B21 -> 1104158 | C27: =+'bid input'!H21 -> 1 | D27: =+'bid input'!I21 -> 0 | E27: =+IF('bid input'!O21=1,"Y","N") -> N | F27: =+'bid input'!K21 -> 0 | G27: =+IF(AND($E27="Y",$C27=G$2,$C27>0),'bid input'!$F21,IF(AND($E27="Y",$D27=G$3,$C27=0),'bid input'!$F21,0))*G$4 -> 0 | H27: =+IF(AND($E27="Y",$C27=H$2,$C27>0),'bid input'!$F21,IF(AND($E27="Y",$D27=H$3,$C27=0),'bid input'!$F21,0))*H$4 -> 0 | I27: =+IF(AND($E27="Y",$C27=I$2,$C27>0),'bid input'!$F21,IF(AND($E27="Y",$D27=I$3,$C27=0),'bid input'!$F21,0))*I$4 -> 0 | J27: =+IF(AND($E27="Y",$C27=J$2,$C27>0),'bid input'!$F21,IF(AND($E27="Y",$D27=J$3,$C27=0),'bid input'!$F21,0))*J$4 -> 0 | K27: =+IF(AND($E27="Y",$C27=K$2,$C27>0),'bid input'!$F21,IF(AND($E27="Y",$D27=K$3,$C27=0),'bid input'!$F21,0))*K$4 -> 0 | L27: =+IF(AND($E27="Y",$C27=L$2,$C27>0),'bid input'!$F21,IF(AND($E27="Y",$D27=L$3,$C27=0),'bid input'!$F21,0))*L$4 -> 0 | M27: =SUM(G27:L27) -> 0
D29: Total Specified/Competitive | G29: =SUM(G8:G28) -> 0 | H29: =SUM(H8:H28) -> 0 | I29: =SUM(I8:I28) -> 0 | J29: =SUM(J8:J28) -> 0 | K29: =SUM(K8:K28) -> 0 | L29: =SUM(L8:L28) -> 0 | M29: =SUM(G29:L29) -> 0
D30: WA Rate | G30: =+IF(G29>0,SUMPRODUCT($F$8:$F$27,G$8:G$27)/G$29,"") | H30: =+IF(H29>0,SUMPRODUCT($F$8:$F$27,H$8:H$27)/H$29,"") | I30: =+IF(I29>0,SUMPRODUCT($F$8:$F$27,I$8:I$27)/I$29,"") | J30: =+IF(J29>0,SUMPRODUCT($F$8:$F$27,J$8:J$27)/J$29,"") | K30: =+IF(K29>0,SUMPRODUCT($F$8:$F$27,K$8:K$27)/K$29,"") | L30: =+IF(L29>0,SUMPRODUCT($F$8:$F$27,L$8:L$27)/L$29,"") | M30: =+SUMPRODUCT(G29:L29,G30:L30)/M29 -> #DIV/0!
D32: Remaining need | G32: =+G4-G29 -> 318725 | H32: =+H4-H29 -> 375685 | I32: =+I4-I29 -> 479875 | J32: =+J4-J29 -> 525400 | K32: =+K4-K29 -> 515425 | L32: =+L4-L29 -> 485000 | M32: =SUM(G32:L32) -> 2700110
D33: Over(under)subscribed | G33: =+IF(G32=0,"NA",IF(G32<0,"OVER","UNDER")) -> UNDER | H33: =+IF(H32=0,"NA",IF(H32<0,"OVER","UNDER")) -> UNDER | I33: =+IF(I32=0,"NA",IF(I32<0,"OVER","UNDER")) -> UNDER | J33: =+IF(J32=0,"NA",IF(J32<0,"OVER","UNDER")) -> UNDER | K33: =+IF(K32=0,"NA",IF(K32<0,"OVER","UNDER")) -> UNDER | L33: =+IF(L32=0,"NA",IF(L32<0,"OVER","UNDER")) -> UNDER | M33: =+IF(M32=0,"NA",IF(M32<0,"OVER","UNDER")) -> UNDER
A35: Step 3 of process - Assets are assigned Specified/Non Competitive bids:
B36: Bid ID | C36: Loan # | D36: MO | E36: Specific & NonCompetitive? | F36: Rate >> | G36: 0.035 | H36: =+G36 -> 0.035 | I36: =+H36 -> 0.035 | J36: =+I36 -> 0.035 | K36: =+J36 -> 0.035 | L36: =+K36 -> 0.035
B37: =+B8 -> 1104134 | C37: =+C8 -> 1 | D37: =+D8 -> 0 | E37: =+IF('bid input'!P2=1,"Y","N") -> Y | G37: =+IF(AND($E37="Y",$C37=G$2,$C37>0),'bid input'!$F2,IF(AND($E37="Y",$D37=G$3,$C37=0),'bid input'!$F2,0))*G$4 -> 63745 | H37: =+IF(AND($E37="Y",$C37=H$2,$C37>0),'bid input'!$F2,IF(AND($E37="Y",$D37=H$3,$C37=0),'bid input'!$F2,0))*H$4 -> 0 | I37: =+IF(AND($E37="Y",$C37=I$2,$C37>0),'bid input'!$F2,IF(AND($E37="Y",$D37=I$3,$C37=0),'bid input'!$F2,0))*I$4 -> 0 | J37: =+IF(AND($E37="Y",$C37=J$2,$C37>0),'bid input'!$F2,IF(AND($E37="Y",$D37=J$3,$C37=0),'bid input'!$F2,0))*J$4 -> 0 | K37: =+IF(AND($E37="Y",$C37=K$2,$C37>0),'bid input'!$F2,IF(AND($E37="Y",$D37=K$3,$C37=0),'bid input'!$F2,0))*K$4 -> 0 | L37: =+IF(AND($E37="Y",$C37=L$2,$C37>0),'bid input'!$F2,IF(AND($E37="Y",$D37=L$3,$C37=0),'bid input'!$F2,0))*L$4 -> 0 | M37: =SUM(G37:L37) -> 63745
B38: =+B9 -> 1104143 | C38: =+C9 -> 0 | D38: =+D9 -> ABC Mortgage | E38: =+IF('bid input'!P3=1,"Y","N") -> Y | G38: =+IF(AND($E38="Y",$C38=G$2,$C38>0),'bid input'!$F3,IF(AND($E38="Y",$D38=G$3,$C38=0),'bid input'!$F3,0))*G$4 -> 63745 | H38: =+IF(AND($E38="Y",$C38=H$2,$C38>0),'bid input'!$F3,IF(AND($E38="Y",$D38=H$3,$C38=0),'bid input'!$F3,0))*H$4 -> 75137 | I38: =+IF(AND($E38="Y",$C38=I$2,$C38>0),'bid input'!$F3,IF(AND($E38="Y",$D38=I$3,$C38=0),'bid input'!$F3,0))*I$4 -> 0 | J38: =+IF(AND($E38="Y",$C38=J$2,$C38>0),'bid input'!$F3,IF(AND($E38="Y",$D38=J$3,$C38=0),'bid input'!$F3,0))*J$4 -> 0 | K38: =+IF(AND($E38="Y",$C38=K$2,$C38>0),'bid input'!$F3,IF(AND($E38="Y",$D38=K$3,$C38=0),'bid input'!$F3,0))*K$4 -> 0 | L38: =+IF(AND($E38="Y",$C38=L$2,$C38>0),'bid input'!$F3,IF(AND($E38="Y",$D38=L$3,$C38=0),'bid input'!$F3,0))*L$4 -> 0 | M38: =SUM(G38:L38) -> 138882
B39: =+B10 -> 1104154 | C39: =+C10 -> 2 | D39: =+D10 -> 0 | E39: =+IF('bid input'!P4=1,"Y","N") -> Y | G39: =+IF(AND($E39="Y",$C39=G$2,$C39>0),'bid input'!$F4,IF(AND($E39="Y",$D39=G$3,$C39=0),'bid input'!$F4,0))*G$4 -> 0 | H39: =+IF(AND($E39="Y",$C39=H$2,$C39>0),'bid input'!$F4,IF(AND($E39="Y",$D39=H$3,$C39=0),'bid input'!$F4,0))*H$4 -> 75137 | I39: =+IF(AND($E39="Y",$C39=I$2,$C39>0),'bid input'!$F4,IF(AND($E39="Y",$D39=I$3,$C39=0),'bid input'!$F4,0))*I$4 -> 0 | J39: =+IF(AND($E39="Y",$C39=J$2,$C39>0),'bid input'!$F4,IF(AND($E39="Y",$D39=J$3,$C39=0),'bid input'!$F4,0))*J$4 -> 0 | K39: =+IF(AND($E39="Y",$C39=K$2,$C39>0),'bid input'!$F4,IF(AND($E39="Y",$D39=K$3,$C39=0),'bid input'!$F4,0))*K$4 -> 0 | L39: =+IF(AND($E39="Y",$C39=L$2,$C39>0),'bid input'!$F4,IF(AND($E39="Y",$D39=L$3,$C39=0),'bid input'!$F4,0))*L$4 -> 0 | M39: =SUM(G39:L39) -> 75137
B40: =+B11 -> 1104152 | C40: =+C11 -> 0 | D40: =+D11 -> Prime Lending | E40: =+IF('bid input'!P5=1,"Y","N") -> Y | G40: =+IF(AND($E40="Y",$C40=G$2,$C40>0),'bid input'!$F5,IF(AND($E40="Y",$D40=G$3,$C40=0),'bid input'!$F5,0))*G$4 -> 0 | H40: =+IF(AND($E40="Y",$C40=H$2,$C40>0),'bid input'!$F5,IF(AND($E40="Y",$D40=H$3,$C40=0),'bid input'!$F5,0))*H$4 -> 0 | I40: =+IF(AND($E40="Y",$C40=I$2,$C40>0),'bid input'!$F5,IF(AND($E40="Y",$D40=I$3,$C40=0),'bid input'!$F5,0))*I$4 -> 95975 | J40: =+IF(AND($E40="Y",$C40=J$2,$C40>0),'bid input'!$F5,IF(AND($E40="Y",$D40=J$3,$C40=0),'bid input'!$F5,0))*J$4 -> 105080 | K40: =+IF(AND($E40="Y",$C40=K$2,$C40>0),'bid input'!$F5,IF(AND($E40="Y",$D40=K$3,$C40=0),'bid input'!$F5,0))*K$4 -> 0 | L40: =+IF(AND($E40="Y",$C40=L$2,$C40>0),'bid input'!$F5,IF(AND($E40="Y",$D40=L$3,$C40=0),'bid input'!$F5,0))*L$4 -> 0 | M40: =SUM(G40:L40) -> 201055
B41: =+B12 -> 1104136 | C41: =+C12 -> 4 | D41: =+D12 -> 0 | E41: =+IF('bid input'!P6=1,"Y","N") -> Y | G41: =+IF(AND($E41="Y",$C41=G$2,$C41>0),'bid input'!$F6,IF(AND($E41="Y",$D41=G$3,$C41=0),'bid input'!$F6,0))*G$4 -> 0 | H41: =+IF(AND($E41="Y",$C41=H$2,$C41>0),'bid input'!$F6,IF(AND($E41="Y",$D41=H$3,$C41=0),'bid input'!$F6,0))*H$4 -> 0 | I41: =+IF(AND($E41="Y",$C41=I$2,$C41>0),'bid input'!$F6,IF(AND($E41="Y",$D41=I$3,$C41=0),'bid input'!$F6,0))*I$4 -> 0 | J41: =+IF(AND($E41="Y",$C41=J$2,$C41>0),'bid input'!$F6,IF(AND($E41="Y",$D41=J$3,$C41=0),'bid input'!$F6,0))*J$4 -> 105080 | K41: =+IF(AND($E41="Y",$C41=K$2,$C41>0),'bid input'!$F6,IF(AND($E41="Y",$D41=K$3,$C41=0),'bid input'!$F6,0))*K$4 -> 0 | L41: =+IF(AND($E41="Y",$C41=L$2,$C41>0),'bid input'!$F6,IF(AND($E41="Y",$D41=L$3,$C41=0),'bid input'!$F6,0))*L$4 -> 0 | M41: =SUM(G41:L41) -> 105080
B42: =+B13 -> 1104138 | C42: =+C13 -> 0 | D42: =+D13 -> Best Loans Inc | E42: =+IF('bid input'!P7=1,"Y","N") -> Y | G42: =+IF(AND($E42="Y",$C42=G$2,$C42>0),'bid input'!$F7,IF(AND($E42="Y",$D42=G$3,$C42=0),'bid input'!$F7,0))*G$4 -> 0 | H42: =+IF(AND($E42="Y",$C42=H$2,$C42>0),'bid input'!$F7,IF(AND($E42="Y",$D42=H$3,$C42=0),'bid input'!$F7,0))*H$4 -> 0 | I42: =+IF(AND($E42="Y",$C42=I$2,$C42>0),'bid input'!$F7,IF(AND($E42="Y",$D42=I$3,$C42=0),'bid input'!$F7,0))*I$4 -> 0 | J42: =+IF(AND($E42="Y",$C42=J$2,$C42>0),'bid input'!$F7,IF(AND($E42="Y",$D42=J$3,$C42=0),'bid input'!$F7,0))*J$4 -> 0 | K42: =+IF(AND($E42="Y",$C42=K$2,$C42>0),'bid input'!$F7,IF(AND($E42="Y",$D42=K$3,$C42=0),'bid input'!$F7,0))*K$4 -> 103085 | L42: =+IF(AND($E42="Y",$C42=L$2,$C42>0),'bid input'!$F7,IF(AND($E42="Y",$D42=L$3,$C42=0),'bid input'!$F7,0))*L$4 -> 0 | M42: =SUM(G42:L42) -> 103085
B43: =+B14 -> 1104139 | C43: =+C14 -> 1 | D43: =+D14 -> 0 | E43: =+IF('bid input'!P8=1,"Y","N") -> Y | G43: =+IF(AND($E43="Y",$C43=G$2,$C43>0),'bid input'!$F8,IF(AND($E43="Y",$D43=G$3,$C43=0),'bid input'!$F8,0))*G$4 -> 63745 | H43: =+IF(AND($E43="Y",$C43=H$2,$C43>0),'bid input'!$F8,IF(AND($E43="Y",$D43=H$3,$C43=0),'bid input'!$F8,0))*H$4 -> 0 | I43: =+IF(AND($E43="Y",$C43=I$2,$C43>0),'bid input'!$F8,IF(AND($E43="Y",$D43=I$3,$C43=0),'bid input'!$F8,0))*I$4 -> 0 | J43: =+IF(AND($E43="Y",$C43=J$2,$C43>0),'bid input'!$F8,IF(AND($E43="Y",$D43=J$3,$C43=0),'bid input'!$F8,0))*J$4 -> 0 | K43: =+IF(AND($E43="Y",$C43=K$2,$C43>0),'bid input'!$F8,IF(AND($E43="Y",$D43=K$3,$C43=0),'bid input'!$F8,0))*K$4 -> 0 | L43: =+IF(AND($E43="Y",$C43=L$2,$C43>0),'bid input'!$F8,IF(AND($E43="Y",$D43=L$3,$C43=0),'bid input'!$F8,0))*L$4 -> 0 | M43: =SUM(G43:L43) -> 63745
B44: =+B15 -> 1104140 | C44: =+C15 -> 5 | D44: =+D15 -> 0 | E44: =+IF('bid input'!P9=1,"Y","N") -> Y | G44: =+IF(AND($E44="Y",$C44=G$2,$C44>0),'bid input'!$F9,IF(AND($E44="Y",$D44=G$3,$C44=0),'bid input'!$F9,0))*G$4 -> 0 | H44: =+IF(AND($E44="Y",$C44=H$2,$C44>0),'bid input'!$F9,IF(AND($E44="Y",$D44=H$3,$C44=0),'bid input'!$F9,0))*H$4 -> 0 | I44: =+IF(AND($E44="Y",$C44=I$2,$C44>0),'bid input'!$F9,IF(AND($E44="Y",$D44=I$3,$C44=0),'bid input'!$F9,0))*I$4 -> 0 | J44: =+IF(AND($E44="Y",$C44=J$2,$C44>0),'bid input'!$F9,IF(AND($E44="Y",$D44=J$3,$C44=0),'bid input'!$F9,0))*J$4 -> 0 | K44: =+IF(AND($E44="Y",$C44=K$2,$C44>0),'bid input'!$F9,IF(AND($E44="Y",$D44=K$3,$C44=0),'bid input'!$F9,0))*K$4 -> 103085 | L44: =+IF(AND($E44="Y",$C44=L$2,$C44>0),'bid input'!$F9,IF(AND($E44="Y",$D44=L$3,$C44=0),'bid input'!$F9,0))*L$4 -> 0 | M44: =SUM(G44:L44) -> 103085
B45: =+B16 -> 1104141 | C45: =+C16 -> 5 | D45: =+D16 -> 0 | E45: =+IF('bid input'!P10=1,"Y","N") -> Y | G45: =+IF(AND($E45="Y",$C45=G$2,$C45>0),'bid input'!$F10,IF(AND($E45="Y",$D45=G$3,$C45=0),'bid input'!$F10,0))*G$4 -> 0 | H45: =+IF(AND($E45="Y",$C45=H$2,$C45>0),'bid input'!$F10,IF(AND($E45="Y",$D45=H$3,$C45=0),'bid input'!$F10,0))*H$4 -> 0 | I45: =+IF(AND($E45="Y",$C45=I$2,$C45>0),'bid input'!$F10,IF(AND($E45="Y",$D45=I$3,$C45=0),'bid input'!$F10,0))*I$4 -> 0 | J45: =+IF(AND($E45="Y",$C45=J$2,$C45>0),'bid input'!$F10,IF(AND($E45="Y",$D45=J$3,$C45=0),'bid input'!$F10,0))*J$4 -> 0 | K45: =+IF(AND($E45="Y",$C45=K$2,$C45>0),'bid input'!$F10,IF(AND($E45="Y",$D45=K$3,$C45=0),'bid input'!$F10,0))*K$4 -> 103085 | L45: =+IF(AND($E45="Y",$C45=L$2,$C45>0),'bid input'!$F10,IF(AND($E45="Y",$D45=L$3,$C45=0),'bid input'!$F10,0))*L$4 -> 0 | M45: =SUM(G45:L45) -> 103085
B46: =+B17 -> 1104159 | C46: =+C17 -> 1 | D46: =+D17 -> 0 | E46: =+IF('bid input'!P11=1,"Y","N") -> Y | G46: =+IF(AND($E46="Y",$C46=G$2,$C46>0),'bid input'!$F11,IF(AND($E46="Y",$D46=G$3,$C46=0),'bid input'!$F11,0))*G$4 -> 63745 | H46: =+IF(AND($E46="Y",$C46=H$2,$C46>0),'bid input'!$F11,IF(AND($E46="Y",$D46=H$3,$C46=0),'bid input'!$F11,0))*H$4 -> 0 | I46: =+IF(AND($E46="Y",$C46=I$2,$C46>0),'bid input'!$F11,IF(AND($E46="Y",$D46=I$3,$C46=0),'bid input'!$F11,0))*I$4 -> 0 | J46: =+IF(AND($E46="Y",$C46=J$2,$C46>0),'bid input'!$F11,IF(AND($E46="Y",$D46=J$3,$C46=0),'bid input'!$F11,0))*J$4 -> 0 | K46: =+IF(AND($E46="Y",$C46=K$2,$C46>0),'bid input'!$F11,IF(AND($E46="Y",$D46=K$3,$C46=0),'bid input'!$F11,0))*K$4 -> 0 | L46: =+IF(AND($E46="Y",$C46=L$2,$C46>0),'bid input'!$F11,IF(AND($E46="Y",$D46=L$3,$C46=0),'bid input'!$F11,0))*L$4 -> 0 | M46: =SUM(G46:L46) -> 63745
B47: =+B18 -> 1104161 | C47: =+C18 -> 4 | D47: =+D18 -> 0 | E47: =+IF('bid input'!P12=1,"Y","N") -> Y | G47: =+IF(AND($E47="Y",$C47=G$2,$C47>0),'bid input'!$F12,IF(AND($E47="Y",$D47=G$3,$C47=0),'bid input'!$F12,0))*G$4 -> 0 | H47: =+IF(AND($E47="Y",$C47=H$2,$C47>0),'bid input'!$F12,IF(AND($E47="Y",$D47=H$3,$C47=0),'bid input'!$F12,0))*H$4 -> 0 | I47: =+IF(AND($E47="Y",$C47=I$2,$C47>0),'bid input'!$F12,IF(AND($E47="Y",$D47=I$3,$C47=0),'bid input'!$F12,0))*I$4 -> 0 | J47: =+IF(AND($E47="Y",$C47=J$2,$C47>0),'bid input'!$F12,IF(AND($E47="Y",$D47=J$3,$C47=0),'bid input'!$F12,0))*J$4 -> 105080 | K47: =+IF(AND($E47="Y",$C47=K$2,$C47>0),'bid input'!$F12,IF(AND($E47="Y",$D47=K$3,$C47=0),'bid input'!$F12,0))*K$4 -> 0 | L47: =+IF(AND($E47="Y",$C47=L$2,$C47>0),'bid input'!$F12,IF(AND($E47="Y",$D47=L$3,$C47=0),'bid input'!$F12,0))*L$4 -> 0 | M47: =SUM(G47:L47) -> 105080
B48: =+B19 -> 1104145 | C48: =+C19 -> 1 | D48: =+D19 -> 0 | E48: =+IF('bid input'!P13=1,"Y","N") -> Y | G48: =+IF(AND($E48="Y",$C48=G$2,$C48>0),'bid input'!$F13,IF(AND($E48="Y",$D48=G$3,$C48=0),'bid input'!$F13,0))*G$4 -> 31872.5 | H48: =+IF(AND($E48="Y",$C48=H$2,$C48>0),'bid input'!$F13,IF(AND($E48="Y",$D48=H$3,$C48=0),'bid input'!$F13,0))*H$4 -> 0 | I48: =+IF(AND($E48="Y",$C48=I$2,$C48>0),'bid input'!$F13,IF(AND($E48="Y",$D48=I$3,$C48=0),'bid input'!$F13,0))*I$4 -> 0 | J48: =+IF(AND($E48="Y",$C48=J$2,$C48>0),'bid input'!$F13,IF(AND($E48="Y",$D48=J$3,$C48=0),'bid input'!$F13,0))*J$4 -> 0 | K48: =+IF(AND($E48="Y",$C48=K$2,$C48>0),'bid input'!$F13,IF(AND($E48="Y",$D48=K$3,$C48=0),'bid input'!$F13,0))*K$4 -> 0 | L48: =+IF(AND($E48="Y",$C48=L$2,$C48>0),'bid input'!$F13,IF(AND($E48="Y",$D48=L$3,$C48=0),'bid input'!$F13,0))*L$4 -> 0 | M48: =SUM(G48:L48) -> 31872.5
... B50: =+B21 -> 1104149 | C50: =+C21 -> 5 | D50: =+D21 -> 0 | E50: =+IF('bid input'!P15=1,"Y","N") -> Y | G50: =+IF(AND($E50="Y",$C50=G$2,$C50>0),'bid input'!$F15,IF(AND($E50="Y",$D50=G$3,$C50=0),'bid input'!$F15,0))*G$4 -> 0 | H50: =+IF(AND($E50="Y",$C50=H$2,$C50>0),'bid input'!$F15,IF(AND($E50="Y",$D50=H$3,$C50=0),'bid input'!$F15,0))*H$4 -> 0 | I50: =+IF(AND($E50="Y",$C50=I$2,$C50>0),'bid input'!$F15,IF(AND($E50="Y",$D50=I$3,$C50=0),'bid input'!$F15,0))*I$4 -> 0 | J50: =+IF(AND($E50="Y",$C50=J$2,$C50>0),'bid input'!$F15,IF(AND($E50="Y",$D50=J$3,$C50=0),'bid input'!$F15,0))*J$4 -> 0 | K50: =+IF(AND($E50="Y",$C50=K$2,$C50>0),'bid input'!$F15,IF(AND($E50="Y",$D50=K$3,$C50=0),'bid input'!$F15,0))*K$4 -> 103085 | L50: =+IF(AND($E50="Y",$C50=L$2,$C50>0),'bid input'!$F15,IF(AND($E50="Y",$D50=L$3,$C50=0),'bid input'!$F15,0))*L$4 -> 0 | M50: =SUM(G50:L50) -> 103085
B51: =+B22 -> 1104151 | C51: =+C22 -> 1 | D51: =+D22 -> 0 | E51: =+IF('bid input'!P16=1,"Y","N") -> Y | G51: 31872.5 | H51: =+IF(AND($E51="Y",$C51=H$2,$C51>0),'bid input'!$F16,IF(AND($E51="Y",$D51=H$3,$C51=0),'bid input'!$F16,0))*H$4 -> 0 | I51: =+IF(AND($E51="Y",$C51=I$2,$C51>0),'bid input'!$F16,IF(AND($E51="Y",$D51=I$3,$C51=0),'bid input'!$F16,0))*I$4 -> 0 | J51: =+IF(AND($E51="Y",$C51=J$2,$C51>0),'bid input'!$F16,IF(AND($E51="Y",$D51=J$3,$C51=0),'bid input'!$F16,0))*J$4 -> 0 | K51: =+IF(AND($E51="Y",$C51=K$2,$C51>0),'bid input'!$F16,IF(AND($E51="Y",$D51=K$3,$C51=0),'bid input'!$F16,0))*K$4 -> 0 | L51: =+IF(AND($E51="Y",$C51=L$2,$C51>0),'bid input'!$F16,IF(AND($E51="Y",$D51=L$3,$C51=0),'bid input'!$F16,0))*L$4 -> 0 | M51: =SUM(G51:L51) -> 31872.5
B52: =+B23 -> 1104131 | C52: =+C23 -> 4 | D52: =+D23 -> 0 | E52: =+IF('bid input'!P17=1,"Y","N") -> Y | G52: =+IF(AND($E52="Y",$C52=G$2,$C52>0),'bid input'!$F17,IF(AND($E52="Y",$D52=G$3,$C52=0),'bid input'!$F17,0))*G$4 -> 0 | H52: =+IF(AND($E52="Y",$C52=H$2,$C52>0),'bid input'!$F17,IF(AND($E52="Y",$D52=H$3,$C52=0),'bid input'!$F17,0))*H$4 -> 0 | I52: =+IF(AND($E52="Y",$C52=I$2,$C52>0),'bid input'!$F17,IF(AND($E52="Y",$D52=I$3,$C52=0),'bid input'!$F17,0))*I$4 -> 0 | J52: =+IF(AND($E52="Y",$C52=J$2,$C52>0),'bid input'!$F17,IF(AND($E52="Y",$D52=J$3,$C52=0),'bid input'!$F17,0))*J$4 -> 105080 | K52: =+IF(AND($E52="Y",$C52=K$2,$C52>0),'bid input'!$F17,IF(AND($E52="Y",$D52=K$3,$C52=0),'bid input'!$F17,0))*K$4 -> 0 | L52: =+IF(AND($E52="Y",$C52=L$2,$C52>0),'bid input'!$F17,IF(AND($E52="Y",$D52=L$3,$C52=0),'bid input'!$F17,0))*L$4 -> 0 | M52: =SUM(G52:L52) -> 105080
...
